[32mINFO    [0m juju.model:__init__.py:3254 Waiting for model:
  postgresql-k8s/0 [idle] active: Primary
  postgresql-k8s/1 [idle] active: 
  postgresql-k8s/2 [idle] active: 
  pgbouncer-k8s/0 [executing] active: 
  pgbouncer-k8s/1 [executing] active: 
[32mINFO    [0m juju.model:__init__.py:3254 Waiting for model:
  pgbouncer-k8s/0 [idle] active: 
  pgbouncer-k8s/1 [idle] active: 
[32mINFO    [0m juju.model:__init__.py:3254 Waiting for model:
  pgbouncer-k8s/0 [idle] blocked: waiting for backend database relation to initialise
  pgbouncer-k8s/1 [idle] blocked: waiting for backend database relation to initialise
[32mINFO    [0m pytest_operator.plugin:plugin.py:929 Model status:

Model  Controller          Cloud/Region        Version  SLA          Timestamp
test   microk8s-localhost  microk8s/localhost  3.6.2    unsupported  01:39:37Z

App             Version  Status   Scale  Charm           Channel  Rev  Address         Exposed  Message
pgbouncer-k8s   1.21.0   blocked      2  pgbouncer-k8s              0  10.152.183.157  no       waiting for backend database relation to initialise
postgresql-k8s  14.15    active       0  postgresql-k8s  14/edge  493  10.152.183.28   no       

Unit               Workload    Agent      Address      Ports  Message
pgbouncer-k8s/0    blocked     idle       10.1.80.200         waiting for backend database relation to initialise
pgbouncer-k8s/1*   blocked     idle       10.1.80.202         waiting for backend database relation to initialise
postgresql-k8s/0   terminated  executing  10.1.80.207         (remove) 
postgresql-k8s/1*  terminated  executing  10.1.80.209         (remove) 
postgresql-k8s/2   terminated  executing  10.1.80.208         (remove) 

[32mINFO    [0m pytest_operator.plugin:plugin.py:935 Juju error logs:

controller-0: 01:38:47 ERROR juju.worker.caasapplicationprovisioner.runner exited "finos-waltz": getting OCI image resources: unable to fetch OCI image resources for finos-waltz: application "finos-waltz" dying or dead
unit-postgresql-k8s-1: 01:39:26 ERROR unit.postgresql-k8s/1.juju-log failed to patch k8s Endpoints postgresql-k8s-primary
Traceback (most recent call last):
  File "/var/lib/juju/agents/unit-postgresql-k8s-1/charm/venv/lib/python3.10/site-packages/lightkube/core/generic_client.py", line 299, in raise_for_status
    resp.raise_for_status()
  File "/var/lib/juju/agents/unit-postgresql-k8s-1/charm/venv/lib/python3.10/site-packages/httpx/_models.py", line 829, in raise_for_status
    raise HTTPStatusError(message, request=request, response=self)
httpx.HTTPStatusError: Client error '409 Conflict' for url 'https://10.152.183.1/api/v1/namespaces/test/endpoints/postgresql-k8s-primary?force=true&fieldManager=postgresql-k8s'
For more information check: https://developer.mozilla.org/en-US/docs/Web/HTTP/Status/409

During handling of the above exception, another exception occurred:

Traceback (most recent call last):
  File "/var/lib/juju/agents/unit-postgresql-k8s-1/charm/src/charm.py", line 1355, in _on_stop
    client.apply(
  File "/var/lib/juju/agents/unit-postgresql-k8s-1/charm/venv/lib/python3.10/site-packages/lightkube/core/client.py", line 757, in apply
    return self.patch(
  File "/var/lib/juju/agents/unit-postgresql-k8s-1/charm/venv/lib/python3.10/site-packages/lightkube/core/client.py", line 492, in patch
    return self._client.request(
  File "/var/lib/juju/agents/unit-postgresql-k8s-1/charm/venv/lib/python3.10/site-packages/lightkube/core/generic_client.py", line 383, in request
    return self.handle_response(method, resp, br)
  File "/var/lib/juju/agents/unit-postgresql-k8s-1/charm/venv/lib/python3.10/site-packages/lightkube/core/generic_client.py", line 315, in handle_response
    self.raise_for_status(resp)
  File "/var/lib/juju/agents/unit-postgresql-k8s-1/charm/venv/lib/python3.10/site-packages/lightkube/core/generic_client.py", line 301, in raise_for_status
    raise transform_exception(e)
lightkube.core.exceptions.ApiError: Operation cannot be fulfilled on endpoints "postgresql-k8s-primary": the object has been modified; please apply your changes to the latest version and try again
unit-postgresql-k8s-1: 01:39:26 ERROR unit.postgresql-k8s/1.juju-log failed to patch k8s Endpoints postgresql-k8s-replicas
Traceback (most recent call last):
  File "/var/lib/juju/agents/unit-postgresql-k8s-1/charm/venv/lib/python3.10/site-packages/lightkube/core/generic_client.py", line 299, in raise_for_status
    resp.raise_for_status()
  File "/var/lib/juju/agents/unit-postgresql-k8s-1/charm/venv/lib/python3.10/site-packages/httpx/_models.py", line 829, in raise_for_status
    raise HTTPStatusError(message, request=request, response=self)
httpx.HTTPStatusError: Client error '409 Conflict' for url 'https://10.152.183.1/api/v1/namespaces/test/endpoints/postgresql-k8s-replicas?force=true&fieldManager=postgresql-k8s'
For more information check: https://developer.mozilla.org/en-US/docs/Web/HTTP/Status/409

During handling of the above exception, another exception occurred:

Traceback (most recent call last):
  File "/var/lib/juju/agents/unit-postgresql-k8s-1/charm/src/charm.py", line 1355, in _on_stop
    client.apply(
  File "/var/lib/juju/agents/unit-postgresql-k8s-1/charm/venv/lib/python3.10/site-packages/lightkube/core/client.py", line 757, in apply
    return self.patch(
  File "/var/lib/juju/agents/unit-postgresql-k8s-1/charm/venv/lib/python3.10/site-packages/lightkube/core/client.py", line 492, in patch
    return self._client.request(
  File "/var/lib/juju/agents/unit-postgresql-k8s-1/charm/venv/lib/python3.10/site-packages/lightkube/core/generic_client.py", line 383, in request
    return self.handle_response(method, resp, br)
  File "/var/lib/juju/agents/unit-postgresql-k8s-1/charm/venv/lib/python3.10/site-packages/lightkube/core/generic_client.py", line 315, in handle_response
    self.raise_for_status(resp)
  File "/var/lib/juju/agents/unit-postgresql-k8s-1/charm/venv/lib/python3.10/site-packages/lightkube/core/generic_client.py", line 301, in raise_for_status
    raise transform_exception(e)
lightkube.core.exceptions.ApiError: Operation cannot be fulfilled on endpoints "postgresql-k8s-replicas": the object has been modified; please apply your changes to the latest version and try again
unit-postgresql-k8s-1: 01:39:26 ERROR unit.postgresql-k8s/1.juju-log failed to patch k8s Service patroni-postgresql-k8s-config
Traceback (most recent call last):
  File "/var/lib/juju/agents/unit-postgresql-k8s-1/charm/venv/lib/python3.10/site-packages/lightkube/core/generic_client.py", line 299, in raise_for_status
    resp.raise_for_status()
  File "/var/lib/juju/agents/unit-postgresql-k8s-1/charm/venv/lib/python3.10/site-packages/httpx/_models.py", line 829, in raise_for_status
    raise HTTPStatusError(message, request=request, response=self)
httpx.HTTPStatusError: Client error '409 Conflict' for url 'https://10.152.183.1/api/v1/namespaces/test/services/patroni-postgresql-k8s-config?force=true&fieldManager=postgresql-k8s'
For more information check: https://developer.mozilla.org/en-US/docs/Web/HTTP/Status/409

During handling of the above exception, another exception occurred:

Traceback (most recent call last):
  File "/var/lib/juju/agents/unit-postgresql-k8s-1/charm/src/charm.py", line 1355, in _on_stop
    client.apply(
  File "/var/lib/juju/agents/unit-postgresql-k8s-1/charm/venv/lib/python3.10/site-packages/lightkube/core/client.py", line 757, in apply
    return self.patch(
  File "/var/lib/juju/agents/unit-postgresql-k8s-1/charm/venv/lib/python3.10/site-packages/lightkube/core/client.py", line 492, in patch
    return self._client.request(
  File "/var/lib/juju/agents/unit-postgresql-k8s-1/charm/venv/lib/python3.10/site-packages/lightkube/core/generic_client.py", line 383, in request
    return self.handle_response(method, resp, br)
  File "/var/lib/juju/agents/unit-postgresql-k8s-1/charm/venv/lib/python3.10/site-packages/lightkube/core/generic_client.py", line 315, in handle_response
    self.raise_for_status(resp)
  File "/var/lib/juju/agents/unit-postgresql-k8s-1/charm/venv/lib/python3.10/site-packages/lightkube/core/generic_client.py", line 301, in raise_for_status
    raise transform_exception(e)
lightkube.core.exceptions.ApiError: Operation cannot be fulfilled on services "patroni-postgresql-k8s-config": the object has been modified; please apply your changes to the latest version and try again

[32mINFO    [0m pytest_operator.plugin:plugin.py:1017 Forgetting model main...