[32mINFO    [0m integration.test_upgrade_from_stable:test_upgrade_from_stable.py:107 starting continuous writes to the database
[32mINFO    [0m integration.test_upgrade_from_stable:test_upgrade_from_stable.py:111 checking whether writes are increasing
[32mINFO    [0m httpx:_client.py:1025 HTTP Request: GET https://10.1.1.144:16443/api/v1/namespaces/testing/pods/postgresql-k8s-0 "HTTP/1.1 200 OK"
[32mINFO    [0m httpx:_client.py:1025 HTTP Request: GET https://10.1.1.144:16443/api/v1/namespaces/testing/pods/postgresql-k8s-1 "HTTP/1.1 200 OK"
[32mINFO    [0m httpx:_client.py:1025 HTTP Request: GET https://10.1.1.144:16443/api/v1/namespaces/testing/pods/postgresql-k8s-2 "HTTP/1.1 200 OK"
[32mINFO    [0m httpx:_client.py:1025 HTTP Request: GET https://10.1.1.144:16443/api/v1/namespaces/testing/pods/postgresql-k8s-0 "HTTP/1.1 200 OK"
[32mINFO    [0m httpx:_client.py:1025 HTTP Request: GET https://10.1.1.144:16443/api/v1/namespaces/testing/pods/postgresql-k8s-1 "HTTP/1.1 200 OK"
[32mINFO    [0m httpx:_client.py:1025 HTTP Request: GET https://10.1.1.144:16443/api/v1/namespaces/testing/pods/postgresql-k8s-2 "HTTP/1.1 200 OK"
[32mINFO    [0m httpx:_client.py:1025 HTTP Request: GET https://10.1.1.144:16443/api/v1/namespaces/testing/pods/postgresql-k8s-0 "HTTP/1.1 200 OK"
[32mINFO    [0m httpx:_client.py:1025 HTTP Request: GET https://10.1.1.144:16443/api/v1/namespaces/testing/pods/postgresql-k8s-1 "HTTP/1.1 200 OK"
[32mINFO    [0m httpx:_client.py:1025 HTTP Request: GET https://10.1.1.144:16443/api/v1/namespaces/testing/pods/postgresql-k8s-2 "HTTP/1.1 200 OK"
[32mINFO    [0m httpx:_client.py:1025 HTTP Request: GET https://10.1.1.144:16443/api/v1/namespaces/testing/pods/postgresql-k8s-0 "HTTP/1.1 200 OK"
[32mINFO    [0m httpx:_client.py:1025 HTTP Request: GET https://10.1.1.144:16443/api/v1/namespaces/testing/pods/postgresql-k8s-1 "HTTP/1.1 200 OK"
[32mINFO    [0m httpx:_client.py:1025 HTTP Request: GET https://10.1.1.144:16443/api/v1/namespaces/testing/pods/postgresql-k8s-2 "HTTP/1.1 200 OK"
[32mINFO    [0m integration.test_upgrade_from_stable:test_upgrade_from_stable.py:117 Refresh the charm
[32mINFO    [0m integration.test_upgrade_from_stable:test_upgrade_from_stable.py:120 Wait for upgrade to complete on first upgrading unit
[32mINFO    [0m juju.model:__init__.py:3254 Waiting for model:
  pgbouncer-k8s/0 [idle] active: 
  pgbouncer-k8s/1 [idle] active: 
  pgbouncer-k8s/2 [idle] active: 
[32mINFO    [0m juju.model:__init__.py:3254 Waiting for model:
  pgbouncer-k8s/0 [executing] waiting: other units upgrading first...
  pgbouncer-k8s/1 [executing] waiting: other units upgrading first...
  pgbouncer-k8s/2 [executing] waiting: pgbouncer not running
[32mINFO    [0m juju.model:__init__.py:3254 Waiting for model:
  pgbouncer-k8s/0 [idle] active: 
  pgbouncer-k8s/1 [idle] active: 
  pgbouncer-k8s/2 [idle] active: 
[32mINFO    [0m integration.test_upgrade_from_stable:test_upgrade_from_stable.py:128 Resume upgrade
[32mINFO    [0m integration.test_upgrade_from_stable:test_upgrade_from_stable.py:133 Wait for upgrade to complete
[32mINFO    [0m juju.model:__init__.py:3254 Waiting for model:
  pgbouncer-k8s/0 [idle] active: 
  pgbouncer-k8s/1 [executing] maintenance: 
  pgbouncer-k8s/2 [idle] active: 
[32mINFO    [0m juju.model:__init__.py:3254 Waiting for model:
  pgbouncer-k8s/0 [executing] maintenance: 
  pgbouncer-k8s/1 [idle] active: 
  pgbouncer-k8s/2 [idle] active: 
[32mINFO    [0m juju.model:__init__.py:3254 Waiting for model:
  pgbouncer-k8s/0 [executing] active: 
  pgbouncer-k8s/1 [idle] active: 
  pgbouncer-k8s/2 [idle] active: 
[32mINFO    [0m juju.model:__init__.py:3254 Waiting for model:
  pgbouncer-k8s/0 [idle] active: 
[32mINFO    [0m integration.test_upgrade_from_stable:test_upgrade_from_stable.py:140 checking whether writes are increasing
[32mINFO    [0m httpx:_client.py:1025 HTTP Request: GET https://10.1.1.144:16443/api/v1/namespaces/testing/pods/postgresql-k8s-0 "HTTP/1.1 200 OK"
[32mINFO    [0m httpx:_client.py:1025 HTTP Request: GET https://10.1.1.144:16443/api/v1/namespaces/testing/pods/postgresql-k8s-1 "HTTP/1.1 200 OK"
[32mINFO    [0m httpx:_client.py:1025 HTTP Request: GET https://10.1.1.144:16443/api/v1/namespaces/testing/pods/postgresql-k8s-2 "HTTP/1.1 200 OK"
[32mINFO    [0m httpx:_client.py:1025 HTTP Request: GET https://10.1.1.144:16443/api/v1/namespaces/testing/pods/postgresql-k8s-0 "HTTP/1.1 200 OK"
[32mINFO    [0m httpx:_client.py:1025 HTTP Request: GET https://10.1.1.144:16443/api/v1/namespaces/testing/pods/postgresql-k8s-1 "HTTP/1.1 200 OK"
[32mINFO    [0m httpx:_client.py:1025 HTTP Request: GET https://10.1.1.144:16443/api/v1/namespaces/testing/pods/postgresql-k8s-2 "HTTP/1.1 200 OK"
[32mINFO    [0m httpx:_client.py:1025 HTTP Request: GET https://10.1.1.144:16443/api/v1/namespaces/testing/pods/postgresql-k8s-0 "HTTP/1.1 200 OK"
[32mINFO    [0m httpx:_client.py:1025 HTTP Request: GET https://10.1.1.144:16443/api/v1/namespaces/testing/pods/postgresql-k8s-1 "HTTP/1.1 200 OK"
[32mINFO    [0m httpx:_client.py:1025 HTTP Request: GET https://10.1.1.144:16443/api/v1/namespaces/testing/pods/postgresql-k8s-2 "HTTP/1.1 200 OK"
[32mINFO    [0m httpx:_client.py:1025 HTTP Request: GET https://10.1.1.144:16443/api/v1/namespaces/testing/pods/postgresql-k8s-0 "HTTP/1.1 200 OK"
[32mINFO    [0m httpx:_client.py:1025 HTTP Request: GET https://10.1.1.144:16443/api/v1/namespaces/testing/pods/postgresql-k8s-1 "HTTP/1.1 200 OK"
[32mINFO    [0m httpx:_client.py:1025 HTTP Request: GET https://10.1.1.144:16443/api/v1/namespaces/testing/pods/postgresql-k8s-2 "HTTP/1.1 200 OK"
[32mINFO    [0m integration.test_upgrade_from_stable:test_upgrade_from_stable.py:145 checking whether no writes were lost
[32mINFO    [0m httpx:_client.py:1025 HTTP Request: GET https://10.1.1.144:16443/api/v1/namespaces/testing/pods/postgresql-k8s-0 "HTTP/1.1 200 OK"
[32mINFO    [0m httpx:_client.py:1025 HTTP Request: GET https://10.1.1.144:16443/api/v1/namespaces/testing/pods/postgresql-k8s-1 "HTTP/1.1 200 OK"
[32mINFO    [0m httpx:_client.py:1025 HTTP Request: GET https://10.1.1.144:16443/api/v1/namespaces/testing/pods/postgresql-k8s-2 "HTTP/1.1 200 OK"
[32mINFO    [0m pytest_operator.plugin:plugin.py:937 Model status:

Model    Controller          Cloud/Region        Version  SLA          Timestamp
testing  concierge-microk8s  microk8s/localhost  3.6.4    unsupported  01:46:53Z

App                  Version  Status  Scale  Charm                Channel      Rev  Address         Exposed  Message
pgbouncer-k8s        1.21.0   active      3  pgbouncer-k8s                       0  10.152.183.152  no       
postgresql-k8s       14.17    active      3  postgresql-k8s       14/edge      537  10.152.183.122  no       
postgresql-test-app           active      1  postgresql-test-app  latest/edge  375  10.152.183.87   no       received database credentials of the first database

Unit                    Workload  Agent  Address     Ports  Message
pgbouncer-k8s/0*        active    idle   10.1.68.85         
pgbouncer-k8s/1         active    idle   10.1.68.84         
pgbouncer-k8s/2         active    idle   10.1.68.83         
postgresql-k8s/0*       active    idle   10.1.68.80         Primary
postgresql-k8s/1        active    idle   10.1.68.81         
postgresql-k8s/2        active    idle   10.1.68.82         
postgresql-test-app/0*  active    idle   10.1.68.73         received database credentials of the first database

[32mINFO    [0m pytest_operator.plugin:plugin.py:943 Juju error logs:

unit-postgresql-k8s-1: 01:39:41 ERROR unit.postgresql-k8s/1.juju-log pgdata folder not found in /var/lib/postgresql/data/pgdata
unit-postgresql-k8s-2: 01:39:41 ERROR unit.postgresql-k8s/2.juju-log pgdata folder not found in /var/lib/postgresql/data/pgdata
unit-pgbouncer-k8s-0: 01:41:09 ERROR unit.pgbouncer-k8s/0.juju-log backend-database:7: Uncaught exception while in charm code:
Traceback (most recent call last):
  File "/var/lib/juju/agents/unit-pgbouncer-k8s-0/charm/venv/lib/python3.10/site-packages/ops/model.py", line 3320, in _run
    result = subprocess.run(args, **kwargs)  # type: ignore
  File "/usr/lib/python3.10/subprocess.py", line 526, in run
    raise CalledProcessError(retcode, process.args,
subprocess.CalledProcessError: Command '('/var/lib/juju/tools/unit-pgbouncer-k8s-0/secret-get', 'secret://708ccfc8-7b2d-4a61-8578-aba757169985/cvhlm8v8g5es7bhpb8cg', '--label', 'backend-database.7.user.secret', '--format=json')' returned non-zero exit status 1.

The above exception was the direct cause of the following exception:

Traceback (most recent call last):
  File "/var/lib/juju/agents/unit-pgbouncer-k8s-0/charm/src/charm.py", line 1138, in <module>
    main(PgBouncerK8sCharm)
  File "/var/lib/juju/agents/unit-pgbouncer-k8s-0/charm/venv/lib/python3.10/site-packages/ops/__init__.py", line 343, in __call__
    return _main.main(charm_class=charm_class, use_juju_for_storage=use_juju_for_storage)
  File "/var/lib/juju/agents/unit-pgbouncer-k8s-0/charm/venv/lib/python3.10/site-packages/ops/_main.py", line 558, in main
    manager.run()
  File "/var/lib/juju/agents/unit-pgbouncer-k8s-0/charm/venv/lib/python3.10/site-packages/ops/_main.py", line 543, in run
    self._emit()
  File "/var/lib/juju/agents/unit-pgbouncer-k8s-0/charm/venv/lib/python3.10/site-packages/ops/_main.py", line 502, in _emit
    self._emit_charm_event(self.dispatcher.event_name)
  File "/var/lib/juju/agents/unit-pgbouncer-k8s-0/charm/venv/lib/python3.10/site-packages/ops/_main.py", line 530, in _emit_charm_event
    event_to_emit.emit(*args, **kwargs)
  File "/var/lib/juju/agents/unit-pgbouncer-k8s-0/charm/venv/lib/python3.10/site-packages/ops/framework.py", line 347, in emit
    framework._emit(event)
  File "/var/lib/juju/agents/unit-pgbouncer-k8s-0/charm/venv/lib/python3.10/site-packages/ops/framework.py", line 906, in _emit
    self._reemit(event_path)
  File "/var/lib/juju/agents/unit-pgbouncer-k8s-0/charm/venv/lib/python3.10/site-packages/ops/framework.py", line 996, in _reemit
    custom_handler(event)
  File "/var/lib/juju/agents/unit-pgbouncer-k8s-0/charm/lib/charms/data_platform_libs/v0/data_interfaces.py", line 3131, in _on_relation_changed_event
    self.relation_data._register_secrets_to_relation(event.relation, diff.added)
  File "/var/lib/juju/agents/unit-pgbouncer-k8s-0/charm/lib/charms/data_platform_libs/v0/data_interfaces.py", line 1759, in _register_secrets_to_relation
    self._register_secret_to_relation(relation.name, relation.id, secret_uri, group)
  File "/var/lib/juju/agents/unit-pgbouncer-k8s-0/charm/lib/charms/data_platform_libs/v0/data_interfaces.py", line 1744, in _register_secret_to_relation
    CachedSecret(self._model, self.component, label, secret_id).meta
  File "/var/lib/juju/agents/unit-pgbouncer-k8s-0/charm/lib/charms/data_platform_libs/v0/data_interfaces.py", line 649, in meta
    self._secret_meta = self._model.get_secret(id=self._secret_uri, label=self.label)
  File "/var/lib/juju/agents/unit-pgbouncer-k8s-0/charm/venv/lib/python3.10/site-packages/ops/model.py", line 308, in get_secret
    content = self._backend.secret_get(id=id, label=label)
  File "/var/lib/juju/agents/unit-pgbouncer-k8s-0/charm/venv/lib/python3.10/site-packages/ops/model.py", line 3692, in secret_get
    result = self._run('secret-get', *args, return_output=True, use_json=True)
  File "/var/lib/juju/agents/unit-pgbouncer-k8s-0/charm/venv/lib/python3.10/site-packages/ops/model.py", line 3322, in _run
    raise ModelError(e.stderr) from e
ops.model.ModelError: ERROR secrets "cvhlm8v8g5es7bhpb8cg-1" is forbidden: User "system:serviceaccount:testing:unit-pgbouncer-k8s-0" cannot get resource "secrets" in API group "" in the namespace "testing"

unit-pgbouncer-k8s-0: 01:41:09 ERROR juju.worker.uniter.operation hook "backend-database-relation-changed" (via hook dispatching script: dispatch) failed: exit status 1
unit-pgbouncer-k8s-2: 01:44:20 ERROR unit.pgbouncer-k8s/2.juju-log pgbouncer not running
unit-pgbouncer-k8s-2: 01:44:22 ERROR unit.pgbouncer-k8s/2.juju-log pgbouncer not running
unit-pgbouncer-k8s-2: 01:44:23 ERROR unit.pgbouncer-k8s/2.juju-log pgbouncer not running
unit-pgbouncer-k8s-2: 01:44:24 ERROR unit.pgbouncer-k8s/2.juju-log pgbouncer not running
unit-pgbouncer-k8s-1: 01:45:18 ERROR unit.pgbouncer-k8s/1.juju-log pgbouncer not running
unit-pgbouncer-k8s-1: 01:45:20 ERROR unit.pgbouncer-k8s/1.juju-log pgbouncer not running
unit-pgbouncer-k8s-1: 01:45:21 ERROR unit.pgbouncer-k8s/1.juju-log pgbouncer not running
unit-pgbouncer-k8s-1: 01:45:23 ERROR unit.pgbouncer-k8s/1.juju-log pgbouncer not running
unit-pgbouncer-k8s-0: 01:45:42 ERROR unit.pgbouncer-k8s/0.juju-log pgbouncer not running
unit-pgbouncer-k8s-0: 01:45:47 ERROR unit.pgbouncer-k8s/0.juju-log pgbouncer not running

[32mINFO    [0m pytest_operator.plugin:plugin.py:1025 Forgetting model main...