{"uid":"22e65611e75008a6","name":"test_expose_external","fullName":"tests.integration.test_expose_external#test_expose_external","historyId":"7750323f37c67d2243b6ad910c6b49b1","time":{"start":1753493937034,"stop":1753495073146,"duration":1136112},"description":"Test the expose-external config option.","descriptionHtml":"<p>Test the expose-external config option.</p>\n","status":"broken","statusMessage":"psycopg2.OperationalError: connection to server at \"10.1.0.128\", port 32450 failed: FATAL:  no pg_hba.conf entry for host \"10.1.98.11\", user \"relation_id_7\", database \"testdatabase\", no encryption","statusTrace":"Traceback (most recent call last):\n  File \"/root/spread_project/.tox/integration/lib/python3.12/site-packages/_pytest/runner.py\", line 344, in from_call\n    result: TResult | None = func()\n                             ^^^^^^\n  File \"/root/spread_project/.tox/integration/lib/python3.12/site-packages/_pytest/runner.py\", line 246, in <lambda>\n    lambda: runtest_hook(item=item, **kwds), when=when, reraise=reraise\n            ^^^^^^^^^^^^^^^^^^^^^^^^^^^^^^^\n  File \"/root/spread_project/.tox/integration/lib/python3.12/site-packages/pluggy/_hooks.py\", line 512, in __call__\n    return self._hookexec(self.name, self._hookimpls.copy(), kwargs, firstresult)\n           ^^^^^^^^^^^^^^^^^^^^^^^^^^^^^^^^^^^^^^^^^^^^^^^^^^^^^^^^^^^^^^^^^^^^^^\n  File \"/root/spread_project/.tox/integration/lib/python3.12/site-packages/pluggy/_manager.py\", line 120, in _hookexec\n    return self._inner_hookexec(hook_name, methods, kwargs, firstresult)\n           ^^^^^^^^^^^^^^^^^^^^^^^^^^^^^^^^^^^^^^^^^^^^^^^^^^^^^^^^^^^^^\n  File \"/root/spread_project/.tox/integration/lib/python3.12/site-packages/pluggy/_callers.py\", line 167, in _multicall\n    raise exception\n  File \"/root/spread_project/.tox/integration/lib/python3.12/site-packages/pluggy/_callers.py\", line 139, in _multicall\n    teardown.throw(exception)\n  File \"/root/spread_project/.tox/integration/lib/python3.12/site-packages/_pytest/logging.py\", line 850, in pytest_runtest_call\n    yield\n  File \"/root/spread_project/.tox/integration/lib/python3.12/site-packages/pluggy/_callers.py\", line 139, in _multicall\n    teardown.throw(exception)\n  File \"/root/spread_project/.tox/integration/lib/python3.12/site-packages/pluggy/_callers.py\", line 53, in run_old_style_hookwrapper\n    return result.get_result()\n           ^^^^^^^^^^^^^^^^^^^\n  File \"/root/spread_project/.tox/integration/lib/python3.12/site-packages/pluggy/_result.py\", line 103, in get_result\n    raise exc.with_traceback(tb)\n  File \"/root/spread_project/.tox/integration/lib/python3.12/site-packages/pluggy/_callers.py\", line 38, in run_old_style_hookwrapper\n    res = yield\n          ^^^^^\n  File \"/root/spread_project/.tox/integration/lib/python3.12/site-packages/pluggy/_callers.py\", line 139, in _multicall\n    teardown.throw(exception)\n  File \"/root/spread_project/.tox/integration/lib/python3.12/site-packages/_pytest/capture.py\", line 900, in pytest_runtest_call\n    return (yield)\n            ^^^^^\n  File \"/root/spread_project/.tox/integration/lib/python3.12/site-packages/pluggy/_callers.py\", line 139, in _multicall\n    teardown.throw(exception)\n  File \"/root/spread_project/.tox/integration/lib/python3.12/site-packages/_pytest/skipping.py\", line 263, in pytest_runtest_call\n    return (yield)\n            ^^^^^\n  File \"/root/spread_project/.tox/integration/lib/python3.12/site-packages/pluggy/_callers.py\", line 121, in _multicall\n    res = hook_impl.function(*args)\n          ^^^^^^^^^^^^^^^^^^^^^^^^^\n  File \"/root/spread_project/.tox/integration/lib/python3.12/site-packages/_pytest/runner.py\", line 178, in pytest_runtest_call\n    item.runtest()\n  File \"/root/spread_project/.tox/integration/lib/python3.12/site-packages/_pytest/python.py\", line 1671, in runtest\n    self.ihook.pytest_pyfunc_call(pyfuncitem=self)\n  File \"/root/spread_project/.tox/integration/lib/python3.12/site-packages/pluggy/_hooks.py\", line 512, in __call__\n    return self._hookexec(self.name, self._hookimpls.copy(), kwargs, firstresult)\n           ^^^^^^^^^^^^^^^^^^^^^^^^^^^^^^^^^^^^^^^^^^^^^^^^^^^^^^^^^^^^^^^^^^^^^^\n  File \"/root/spread_project/.tox/integration/lib/python3.12/site-packages/pluggy/_manager.py\", line 120, in _hookexec\n    return self._inner_hookexec(hook_name, methods, kwargs, firstresult)\n           ^^^^^^^^^^^^^^^^^^^^^^^^^^^^^^^^^^^^^^^^^^^^^^^^^^^^^^^^^^^^^\n  File \"/root/spread_project/.tox/integration/lib/python3.12/site-packages/pluggy/_callers.py\", line 167, in _multicall\n    raise exception\n  File \"/root/spread_project/.tox/integration/lib/python3.12/site-packages/pluggy/_callers.py\", line 139, in _multicall\n    teardown.throw(exception)\n  File \"/root/spread_project/.tox/integration/lib/python3.12/site-packages/pluggy/_callers.py\", line 53, in run_old_style_hookwrapper\n    return result.get_result()\n           ^^^^^^^^^^^^^^^^^^^\n  File \"/root/spread_project/.tox/integration/lib/python3.12/site-packages/pluggy/_result.py\", line 103, in get_result\n    raise exc.with_traceback(tb)\n  File \"/root/spread_project/.tox/integration/lib/python3.12/site-packages/pluggy/_callers.py\", line 38, in run_old_style_hookwrapper\n    res = yield\n          ^^^^^\n  File \"/root/spread_project/.tox/integration/lib/python3.12/site-packages/pluggy/_callers.py\", line 121, in _multicall\n    res = hook_impl.function(*args)\n          ^^^^^^^^^^^^^^^^^^^^^^^^^\n  File \"/root/spread_project/.tox/integration/lib/python3.12/site-packages/_pytest/python.py\", line 157, in pytest_pyfunc_call\n    result = testfunction(**testargs)\n             ^^^^^^^^^^^^^^^^^^^^^^^^\n  File \"/root/spread_project/.tox/integration/lib/python3.12/site-packages/pytest_asyncio/plugin.py\", line 529, in inner\n    _loop.run_until_complete(task)\n  File \"/usr/lib/python3.12/asyncio/base_events.py\", line 687, in run_until_complete\n    return future.result()\n           ^^^^^^^^^^^^^^^\n  File \"/root/spread_project/tests/integration/test_expose_external.py\", line 155, in test_expose_external\n    nodeport_endpoints = await confirm_endpoint_connectivity(ops_test)\n                         ^^^^^^^^^^^^^^^^^^^^^^^^^^^^^^^^^^^^^^^^^^^^^\n  File \"/root/spread_project/tests/integration/test_expose_external.py\", line 65, in confirm_endpoint_connectivity\n    for attempt in tenacity.Retrying(\n  File \"/root/spread_project/.tox/integration/lib/python3.12/site-packages/tenacity/__init__.py\", line 445, in __iter__\n    do = self.iter(retry_state=retry_state)\n         ^^^^^^^^^^^^^^^^^^^^^^^^^^^^^^^^^^\n  File \"/root/spread_project/.tox/integration/lib/python3.12/site-packages/tenacity/__init__.py\", line 378, in iter\n    result = action(retry_state)\n             ^^^^^^^^^^^^^^^^^^^\n  File \"/root/spread_project/.tox/integration/lib/python3.12/site-packages/tenacity/__init__.py\", line 420, in exc_check\n    raise retry_exc.reraise()\n          ^^^^^^^^^^^^^^^^^^^\n  File \"/root/spread_project/.tox/integration/lib/python3.12/site-packages/tenacity/__init__.py\", line 187, in reraise\n    raise self.last_attempt.result()\n          ^^^^^^^^^^^^^^^^^^^^^^^^^^\n  File \"/usr/lib/python3.12/concurrent/futures/_base.py\", line 449, in result\n    return self.__get_result()\n           ^^^^^^^^^^^^^^^^^^^\n  File \"/usr/lib/python3.12/concurrent/futures/_base.py\", line 401, in __get_result\n    raise self._exception\n  File \"/root/spread_project/tests/integration/test_expose_external.py\", line 82, in confirm_endpoint_connectivity\n    psycopg2.connect(\n  File \"/root/spread_project/.tox/integration/lib/python3.12/site-packages/psycopg2/__init__.py\", line 122, in connect\n    conn = _connect(dsn, connection_factory=connection_factory, **kwasync)\n           ^^^^^^^^^^^^^^^^^^^^^^^^^^^^^^^^^^^^^^^^^^^^^^^^^^^^^^^^^^^^^^^\npsycopg2.OperationalError: connection to server at \"10.1.0.128\", port 32450 failed: FATAL:  no pg_hba.conf entry for host \"10.1.98.11\", user \"relation_id_7\", database \"testdatabase\", no encryption","flaky":false,"newFailed":false,"newBroken":false,"newPassed":false,"retriesCount":1,"retriesStatusChange":true,"beforeStages":[{"name":"event_loop","time":{"start":1753493936794,"stop":1753493936794,"duration":0},"status":"passed","steps":[],"attachments":[],"parameters":[],"shouldDisplayMessage":false,"stepsCount":0,"attachmentsCount":0,"hasContent":false,"attachmentStep":false},{"name":"tmp_path_factory","time":{"start":1753493936795,"stop":1753493936795,"duration":0},"status":"passed","steps":[],"attachments":[],"parameters":[],"shouldDisplayMessage":false,"stepsCount":0,"attachmentsCount":0,"hasContent":false,"attachmentStep":false},{"name":"charm","time":{"start":1753493936795,"stop":1753493936795,"duration":0},"status":"passed","steps":[],"attachments":[],"parameters":[],"shouldDisplayMessage":false,"stepsCount":0,"attachmentsCount":0,"hasContent":false,"attachmentStep":false},{"name":"ops_test","time":{"start":1753493936795,"stop":1753493937034,"duration":239},"status":"passed","steps":[],"attachments":[],"parameters":[],"shouldDisplayMessage":false,"stepsCount":0,"attachmentsCount":0,"hasContent":false,"attachmentStep":false},{"name":"abort_on_fail","time":{"start":1753493937034,"stop":1753493937034,"duration":0},"status":"passed","steps":[],"attachments":[],"parameters":[],"shouldDisplayMessage":false,"stepsCount":0,"attachmentsCount":0,"hasContent":false,"attachmentStep":false}],"testStage":{"description":"Test the expose-external config option.","status":"broken","statusMessage":"psycopg2.OperationalError: connection to server at \"10.1.0.128\", port 32450 failed: FATAL:  no pg_hba.conf entry for host \"10.1.98.11\", user \"relation_id_7\", database \"testdatabase\", no encryption","statusTrace":"Traceback (most recent call last):\n  File \"/root/spread_project/.tox/integration/lib/python3.12/site-packages/_pytest/runner.py\", line 344, in from_call\n    result: TResult | None = func()\n                             ^^^^^^\n  File \"/root/spread_project/.tox/integration/lib/python3.12/site-packages/_pytest/runner.py\", line 246, in <lambda>\n    lambda: runtest_hook(item=item, **kwds), when=when, reraise=reraise\n            ^^^^^^^^^^^^^^^^^^^^^^^^^^^^^^^\n  File \"/root/spread_project/.tox/integration/lib/python3.12/site-packages/pluggy/_hooks.py\", line 512, in __call__\n    return self._hookexec(self.name, self._hookimpls.copy(), kwargs, firstresult)\n           ^^^^^^^^^^^^^^^^^^^^^^^^^^^^^^^^^^^^^^^^^^^^^^^^^^^^^^^^^^^^^^^^^^^^^^\n  File \"/root/spread_project/.tox/integration/lib/python3.12/site-packages/pluggy/_manager.py\", line 120, in _hookexec\n    return self._inner_hookexec(hook_name, methods, kwargs, firstresult)\n           ^^^^^^^^^^^^^^^^^^^^^^^^^^^^^^^^^^^^^^^^^^^^^^^^^^^^^^^^^^^^^\n  File \"/root/spread_project/.tox/integration/lib/python3.12/site-packages/pluggy/_callers.py\", line 167, in _multicall\n    raise exception\n  File \"/root/spread_project/.tox/integration/lib/python3.12/site-packages/pluggy/_callers.py\", line 139, in _multicall\n    teardown.throw(exception)\n  File \"/root/spread_project/.tox/integration/lib/python3.12/site-packages/_pytest/logging.py\", line 850, in pytest_runtest_call\n    yield\n  File \"/root/spread_project/.tox/integration/lib/python3.12/site-packages/pluggy/_callers.py\", line 139, in _multicall\n    teardown.throw(exception)\n  File \"/root/spread_project/.tox/integration/lib/python3.12/site-packages/pluggy/_callers.py\", line 53, in run_old_style_hookwrapper\n    return result.get_result()\n           ^^^^^^^^^^^^^^^^^^^\n  File \"/root/spread_project/.tox/integration/lib/python3.12/site-packages/pluggy/_result.py\", line 103, in get_result\n    raise exc.with_traceback(tb)\n  File \"/root/spread_project/.tox/integration/lib/python3.12/site-packages/pluggy/_callers.py\", line 38, in run_old_style_hookwrapper\n    res = yield\n          ^^^^^\n  File \"/root/spread_project/.tox/integration/lib/python3.12/site-packages/pluggy/_callers.py\", line 139, in _multicall\n    teardown.throw(exception)\n  File \"/root/spread_project/.tox/integration/lib/python3.12/site-packages/_pytest/capture.py\", line 900, in pytest_runtest_call\n    return (yield)\n            ^^^^^\n  File \"/root/spread_project/.tox/integration/lib/python3.12/site-packages/pluggy/_callers.py\", line 139, in _multicall\n    teardown.throw(exception)\n  File \"/root/spread_project/.tox/integration/lib/python3.12/site-packages/_pytest/skipping.py\", line 263, in pytest_runtest_call\n    return (yield)\n            ^^^^^\n  File \"/root/spread_project/.tox/integration/lib/python3.12/site-packages/pluggy/_callers.py\", line 121, in _multicall\n    res = hook_impl.function(*args)\n          ^^^^^^^^^^^^^^^^^^^^^^^^^\n  File \"/root/spread_project/.tox/integration/lib/python3.12/site-packages/_pytest/runner.py\", line 178, in pytest_runtest_call\n    item.runtest()\n  File \"/root/spread_project/.tox/integration/lib/python3.12/site-packages/_pytest/python.py\", line 1671, in runtest\n    self.ihook.pytest_pyfunc_call(pyfuncitem=self)\n  File \"/root/spread_project/.tox/integration/lib/python3.12/site-packages/pluggy/_hooks.py\", line 512, in __call__\n    return self._hookexec(self.name, self._hookimpls.copy(), kwargs, firstresult)\n           ^^^^^^^^^^^^^^^^^^^^^^^^^^^^^^^^^^^^^^^^^^^^^^^^^^^^^^^^^^^^^^^^^^^^^^\n  File \"/root/spread_project/.tox/integration/lib/python3.12/site-packages/pluggy/_manager.py\", line 120, in _hookexec\n    return self._inner_hookexec(hook_name, methods, kwargs, firstresult)\n           ^^^^^^^^^^^^^^^^^^^^^^^^^^^^^^^^^^^^^^^^^^^^^^^^^^^^^^^^^^^^^\n  File \"/root/spread_project/.tox/integration/lib/python3.12/site-packages/pluggy/_callers.py\", line 167, in _multicall\n    raise exception\n  File \"/root/spread_project/.tox/integration/lib/python3.12/site-packages/pluggy/_callers.py\", line 139, in _multicall\n    teardown.throw(exception)\n  File \"/root/spread_project/.tox/integration/lib/python3.12/site-packages/pluggy/_callers.py\", line 53, in run_old_style_hookwrapper\n    return result.get_result()\n           ^^^^^^^^^^^^^^^^^^^\n  File \"/root/spread_project/.tox/integration/lib/python3.12/site-packages/pluggy/_result.py\", line 103, in get_result\n    raise exc.with_traceback(tb)\n  File \"/root/spread_project/.tox/integration/lib/python3.12/site-packages/pluggy/_callers.py\", line 38, in run_old_style_hookwrapper\n    res = yield\n          ^^^^^\n  File \"/root/spread_project/.tox/integration/lib/python3.12/site-packages/pluggy/_callers.py\", line 121, in _multicall\n    res = hook_impl.function(*args)\n          ^^^^^^^^^^^^^^^^^^^^^^^^^\n  File \"/root/spread_project/.tox/integration/lib/python3.12/site-packages/_pytest/python.py\", line 157, in pytest_pyfunc_call\n    result = testfunction(**testargs)\n             ^^^^^^^^^^^^^^^^^^^^^^^^\n  File \"/root/spread_project/.tox/integration/lib/python3.12/site-packages/pytest_asyncio/plugin.py\", line 529, in inner\n    _loop.run_until_complete(task)\n  File \"/usr/lib/python3.12/asyncio/base_events.py\", line 687, in run_until_complete\n    return future.result()\n           ^^^^^^^^^^^^^^^\n  File \"/root/spread_project/tests/integration/test_expose_external.py\", line 155, in test_expose_external\n    nodeport_endpoints = await confirm_endpoint_connectivity(ops_test)\n                         ^^^^^^^^^^^^^^^^^^^^^^^^^^^^^^^^^^^^^^^^^^^^^\n  File \"/root/spread_project/tests/integration/test_expose_external.py\", line 65, in confirm_endpoint_connectivity\n    for attempt in tenacity.Retrying(\n  File \"/root/spread_project/.tox/integration/lib/python3.12/site-packages/tenacity/__init__.py\", line 445, in __iter__\n    do = self.iter(retry_state=retry_state)\n         ^^^^^^^^^^^^^^^^^^^^^^^^^^^^^^^^^^\n  File \"/root/spread_project/.tox/integration/lib/python3.12/site-packages/tenacity/__init__.py\", line 378, in iter\n    result = action(retry_state)\n             ^^^^^^^^^^^^^^^^^^^\n  File \"/root/spread_project/.tox/integration/lib/python3.12/site-packages/tenacity/__init__.py\", line 420, in exc_check\n    raise retry_exc.reraise()\n          ^^^^^^^^^^^^^^^^^^^\n  File \"/root/spread_project/.tox/integration/lib/python3.12/site-packages/tenacity/__init__.py\", line 187, in reraise\n    raise self.last_attempt.result()\n          ^^^^^^^^^^^^^^^^^^^^^^^^^^\n  File \"/usr/lib/python3.12/concurrent/futures/_base.py\", line 449, in result\n    return self.__get_result()\n           ^^^^^^^^^^^^^^^^^^^\n  File \"/usr/lib/python3.12/concurrent/futures/_base.py\", line 401, in __get_result\n    raise self._exception\n  File \"/root/spread_project/tests/integration/test_expose_external.py\", line 82, in confirm_endpoint_connectivity\n    psycopg2.connect(\n  File \"/root/spread_project/.tox/integration/lib/python3.12/site-packages/psycopg2/__init__.py\", line 122, in connect\n    conn = _connect(dsn, connection_factory=connection_factory, **kwasync)\n           ^^^^^^^^^^^^^^^^^^^^^^^^^^^^^^^^^^^^^^^^^^^^^^^^^^^^^^^^^^^^^^^\npsycopg2.OperationalError: connection to server at \"10.1.0.128\", port 32450 failed: FATAL:  no pg_hba.conf entry for host \"10.1.98.11\", user \"relation_id_7\", database \"testdatabase\", no encryption","steps":[],"attachments":[{"uid":"c07afc98553c524b","name":"log","source":"c07afc98553c524b.txt","type":"text/plain","size":3698}],"parameters":[],"shouldDisplayMessage":true,"stepsCount":0,"attachmentsCount":1,"hasContent":true,"attachmentStep":false},"afterStages":[{"name":"abort_on_fail::0","time":{"start":1753495073152,"stop":1753495073153,"duration":1},"status":"passed","steps":[],"attachments":[],"parameters":[],"shouldDisplayMessage":false,"stepsCount":0,"attachmentsCount":0,"hasContent":false,"attachmentStep":false},{"name":"ops_test::finalizer","time":{"start":1753495073159,"stop":1753495073554,"duration":395},"status":"passed","steps":[],"attachments":[],"parameters":[],"shouldDisplayMessage":false,"stepsCount":0,"attachmentsCount":0,"hasContent":false,"attachmentStep":false},{"name":"event_loop::2","time":{"start":1753495073555,"stop":1753495073555,"duration":0},"status":"passed","steps":[],"attachments":[],"parameters":[],"shouldDisplayMessage":false,"stepsCount":0,"attachmentsCount":0,"hasContent":false,"attachmentStep":false},{"name":"event_loop::_close_event_loop","time":{"start":1753495073555,"stop":1753495073555,"duration":0},"status":"passed","steps":[],"attachments":[],"parameters":[],"shouldDisplayMessage":false,"stepsCount":0,"attachmentsCount":0,"hasContent":false,"attachmentStep":false},{"name":"event_loop::_provide_clean_event_loop","time":{"start":1753495073555,"stop":1753495073556,"duration":1},"status":"passed","steps":[],"attachments":[],"parameters":[],"shouldDisplayMessage":false,"stepsCount":0,"attachmentsCount":0,"hasContent":false,"attachmentStep":false}],"labels":[{"name":"tag","value":"abort_on_fail"},{"name":"tag","value":"asyncio"},{"name":"tag","value":"asyncio"},{"name":"parentSuite","value":"tests.integration"},{"name":"suite","value":"test_expose_external"},{"name":"host","value":"pkrvmpptgkbjq6m"},{"name":"thread","value":"21846-MainThread"},{"name":"framework","value":"pytest"},{"name":"language","value":"cpython3"},{"name":"package","value":"tests.integration.test_expose_external"},{"name":"resultFormat","value":"allure2"}],"parameters":[],"links":[],"hidden":false,"retry":false,"extra":{"severity":"normal","retries":[{"uid":"998fca714588fd73","status":"unknown","time":{}}],"categories":[{"name":"Test defects","matchedStatuses":[]}],"history":{"statistic":{"failed":0,"broken":22,"skipped":0,"passed":123,"unknown":16,"total":161},"items":[{"uid":"dd368ca89f6af30","reportUrl":"../2881//#testresult/dd368ca89f6af30","status":"broken","statusDetails":"psycopg2.OperationalError: connection to server at \"10.1.0.131\", port 31799 failed: FATAL:  no pg_hba.conf entry for host \"10.1.98.11\", user \"relation_id_7\", database \"testdatabase\", no encryption","time":{"start":1753407816547,"stop":1753408952142,"duration":1135595}},{"uid":"f88180071b226870","reportUrl":"../2880//#testresult/f88180071b226870","status":"passed","time":{"start":1753321336145,"stop":1753321563621,"duration":227476}},{"uid":"b9c80d697b3f95d0","reportUrl":"../2877//#testresult/b9c80d697b3f95d0","status":"passed","time":{"start":1753234939371,"stop":1753235339124,"duration":399753}},{"uid":"145e9d24a9dd1a26","reportUrl":"../2874//#testresult/145e9d24a9dd1a26","status":"passed","time":{"start":1753149128529,"stop":1753149357861,"duration":229332}},{"uid":"83dbeae2335ea3b","reportUrl":"../2873//#testresult/83dbeae2335ea3b","status":"unknown","time":{}},{"uid":"3c1d0c069d317ca1","reportUrl":"../2872//#testresult/3c1d0c069d317ca1","status":"passed","time":{"start":1752975536586,"stop":1752975851259,"duration":314673}},{"uid":"55cd3278fd40c827","reportUrl":"../2871//#testresult/55cd3278fd40c827","status":"broken","statusDetails":"psycopg2.OperationalError: connection to server at \"10.1.0.150\", port 32729 failed: FATAL:  no pg_hba.conf entry for host \"10.1.63.203\", user \"relation_id_7\", database \"testdatabase\", no encryption","time":{"start":1752889183472,"stop":1752890301060,"duration":1117588}},{"uid":"9023d90013f1f440","reportUrl":"../2870//#testresult/9023d90013f1f440","status":"broken","statusDetails":"psycopg2.OperationalError: connection to server at \"10.1.0.145\", port 30280 failed: FATAL:  no pg_hba.conf entry for host \"10.1.63.202\", user \"relation_id_7\", database \"testdatabase\", no encryption","time":{"start":1752802718976,"stop":1752803818357,"duration":1099381}},{"uid":"eee2d9147d88db0b","reportUrl":"../2869//#testresult/eee2d9147d88db0b","status":"passed","time":{"start":1752716130320,"stop":1752716354561,"duration":224241}},{"uid":"a7563414312c70b2","reportUrl":"../2868//#testresult/a7563414312c70b2","status":"broken","statusDetails":"psycopg2.OperationalError: connection to server at \"10.1.0.143\", port 32664 failed: FATAL:  no pg_hba.conf entry for host \"10.1.63.202\", user \"relation_id_7\", database \"testdatabase\", no encryption","time":{"start":1752630234411,"stop":1752631351881,"duration":1117470}},{"uid":"48758b8fb61fd2f3","reportUrl":"../2867//#testresult/48758b8fb61fd2f3","status":"broken","statusDetails":"psycopg2.OperationalError: connection to server at \"10.1.0.189\", port 31268 failed: FATAL:  no pg_hba.conf entry for host \"10.1.63.203\", user \"relation_id_7\", database \"testdatabase\", no encryption","time":{"start":1752543983462,"stop":1752545108492,"duration":1125030}},{"uid":"53ffb90a155f5d4b","reportUrl":"../2864//#testresult/53ffb90a155f5d4b","status":"broken","statusDetails":"psycopg2.OperationalError: connection to server at \"10.1.0.126\", port 32376 failed: FATAL:  no pg_hba.conf entry for host \"10.1.63.202\", user \"relation_id_7\", database \"testdatabase\", no encryption","time":{"start":1752456768220,"stop":1752457889577,"duration":1121357}},{"uid":"4657310d5ae163ff","reportUrl":"../2863//#testresult/4657310d5ae163ff","status":"broken","statusDetails":"psycopg2.OperationalError: connection to server at \"10.1.0.132\", port 30305 failed: FATAL:  no pg_hba.conf entry for host \"10.1.63.203\", user \"relation_id_7\", database \"testdatabase\", no encryption","time":{"start":1752370857870,"stop":1752371977663,"duration":1119793}},{"uid":"a2fe9a240d87159f","reportUrl":"../2862//#testresult/a2fe9a240d87159f","status":"broken","statusDetails":"psycopg2.OperationalError: connection to server at \"10.1.0.18\", port 30237 failed: FATAL:  no pg_hba.conf entry for host \"10.1.169.138\", user \"relation_id_7\", database \"testdatabase\", no encryption","time":{"start":1752284624029,"stop":1752285720132,"duration":1096103}},{"uid":"43aef7967daefdc1","reportUrl":"../2861//#testresult/43aef7967daefdc1","status":"passed","time":{"start":1752198233590,"stop":1752198475546,"duration":241956}},{"uid":"76d931c45e534910","reportUrl":"../2860//#testresult/76d931c45e534910","status":"broken","statusDetails":"psycopg2.OperationalError: connection to server at \"10.1.0.138\", port 32360 failed: FATAL:  no pg_hba.conf entry for host \"10.1.169.137\", user \"relation_id_7\", database \"testdatabase\", no encryption","time":{"start":1752111878903,"stop":1752112980136,"duration":1101233}},{"uid":"9acc12e0d76e033","reportUrl":"../2859//#testresult/9acc12e0d76e033","status":"passed","time":{"start":1752024995894,"stop":1752025238549,"duration":242655}},{"uid":"d9aff47e6c63a778","reportUrl":"../2855//#testresult/d9aff47e6c63a778","status":"passed","time":{"start":1751938948496,"stop":1751939166935,"duration":218439}},{"uid":"88fdc733562ca7af","reportUrl":"../2854//#testresult/88fdc733562ca7af","status":"broken","statusDetails":"psycopg2.OperationalError: connection to server at \"10.1.0.212\", port 31965 failed: FATAL:  no pg_hba.conf entry for host \"10.1.32.74\", user \"relation_id_7\", database \"testdatabase\", no encryption","time":{"start":1751851998100,"stop":1751853116072,"duration":1117972}},{"uid":"acda6c472a3722e0","reportUrl":"../2853//#testresult/acda6c472a3722e0","status":"broken","statusDetails":"psycopg2.OperationalError: connection to server at \"10.1.0.192\", port 30588 failed: FATAL:  no pg_hba.conf entry for host \"10.1.32.75\", user \"relation_id_7\", database \"testdatabase\", no encryption","time":{"start":1751765594014,"stop":1751766698063,"duration":1104049}}]},"tags":["asyncio","abort_on_fail"]},"source":"22e65611e75008a6.json","parameterValues":[]}