[32mINFO    [0m pytest_operator.plugin:plugin.py:937 Model status:

Model    Controller          Cloud/Region        Version  SLA          Timestamp
testing  concierge-microk8s  microk8s/localhost  3.6.8    unsupported  01:45:59Z

App                       Version  Status  Scale  Charm                     Channel        Rev  Address         Exposed  Message
pgbouncer-k8s             1.21.0   active      2  pgbouncer-k8s                              0  10.152.183.82   no       
postgresql-k8s            14.18    active      3  postgresql-k8s            14/edge        616  10.152.183.61   no       
postgresql-test-app                active      1  postgresql-test-app       latest/edge    392  10.152.183.97   no       
self-signed-certificates           active      1  self-signed-certificates  latest/stable  264  10.152.183.204  no       

Unit                         Workload  Agent  Address     Ports  Message
pgbouncer-k8s/0              active    idle   10.1.98.9          
pgbouncer-k8s/1*             active    idle   10.1.98.10         
postgresql-k8s/0*            active    idle   10.1.98.16         Primary
postgresql-k8s/1             active    idle   10.1.98.18         
postgresql-k8s/2             active    idle   10.1.98.17         
postgresql-test-app/0*       active    idle   10.1.98.11         
self-signed-certificates/0*  active    idle   10.1.98.12         

[32mINFO    [0m pytest_operator.plugin:plugin.py:943 Juju error logs:

controller-0: 01:38:39 ERROR juju.worker.caasapplicationprovisioner.runner exited "pgbouncer-k8s": refreshing application status for "pgbouncer-k8s": rpc error: code = Unavailable desc = error reading from server: read unix @->/var/snap/microk8s/8155/var/kubernetes/backend/kine.sock:12379: read: connection reset by peer
unit-pgbouncer-k8s-1: 01:39:30 ERROR unit.pgbouncer-k8s/1.juju-log backend-database:7: deferring database-created hook - postgres database not ready
unit-pgbouncer-k8s-1: 01:39:38 ERROR unit.pgbouncer-k8s/1.juju-log deferring database-created hook - postgres database not ready
unit-pgbouncer-k8s-1: 01:39:48 ERROR unit.pgbouncer-k8s/1.juju-log deferring database-created hook - postgres database not ready
unit-pgbouncer-k8s-1: 01:40:00 ERROR unit.pgbouncer-k8s/1.juju-log deferring database-created hook - postgres database not ready
unit-pgbouncer-k8s-1: 01:40:18 ERROR unit.pgbouncer-k8s/1.juju-log pgb-peers:0: 
Traceback (most recent call last):
  File "/var/lib/juju/agents/unit-pgbouncer-k8s-1/charm/lib/charms/postgresql_k8s/v0/postgresql.py", line 451, in enable_disable_extensions
    with self._connect_to_database(
  File "/var/lib/juju/agents/unit-pgbouncer-k8s-1/charm/lib/charms/postgresql_k8s/v0/postgresql.py", line 184, in _connect_to_database
    connection = psycopg2.connect(
  File "/var/lib/juju/agents/unit-pgbouncer-k8s-1/charm/venv/lib/python3.10/site-packages/psycopg2/__init__.py", line 122, in connect
    conn = _connect(dsn, connection_factory=connection_factory, **kwasync)
psycopg2.OperationalError: connection to server at "postgresql-k8s-primary.testing.svc.cluster.local" (10.152.183.142), port 5432 failed: FATAL:  no pg_hba.conf entry for host "10.1.98.10", user "relation_id_7", database "postgresql_test_app_database", no encryption


The above exception was the direct cause of the following exception:

Traceback (most recent call last):
  File "/var/lib/juju/agents/unit-pgbouncer-k8s-1/charm/src/relations/pgbouncer_provider.py", line 162, in _on_database_requested
    self.charm.backend.postgres.create_database(
  File "/var/lib/juju/agents/unit-pgbouncer-k8s-1/charm/lib/charms/postgresql_k8s/v0/postgresql.py", line 270, in create_database
    self.enable_disable_extensions(dict.fromkeys(plugins, True), database)
  File "/var/lib/juju/agents/unit-pgbouncer-k8s-1/charm/lib/charms/postgresql_k8s/v0/postgresql.py", line 466, in enable_disable_extensions
    raise PostgreSQLEnableDisableExtensionError() from e
charms.postgresql_k8s.v0.postgresql.PostgreSQLEnableDisableExtensionError
unit-postgresql-k8s-2: 01:41:14 ERROR unit.postgresql-k8s/2.juju-log pgdata folder not found in /var/lib/postgresql/data/pgdata
unit-postgresql-k8s-1: 01:41:14 ERROR unit.postgresql-k8s/1.juju-log pgdata folder not found in /var/lib/postgresql/data/pgdata
unit-postgresql-k8s-1: 01:41:23 ERROR unit.postgresql-k8s/1.juju-log pgdata folder not found in /var/lib/postgresql/data/pgdata
unit-postgresql-k8s-2: 01:41:23 ERROR unit.postgresql-k8s/2.juju-log pgdata folder not found in /var/lib/postgresql/data/pgdata
unit-postgresql-k8s-1: 01:41:32 ERROR unit.postgresql-k8s/1.juju-log pgdata folder not found in /var/lib/postgresql/data/pgdata
unit-postgresql-k8s-2: 01:41:32 ERROR unit.postgresql-k8s/2.juju-log pgdata folder not found in /var/lib/postgresql/data/pgdata
unit-postgresql-k8s-2: 01:41:41 ERROR unit.postgresql-k8s/2.juju-log pgdata folder not found in /var/lib/postgresql/data/pgdata
unit-postgresql-k8s-1: 01:41:42 ERROR unit.postgresql-k8s/1.juju-log pgdata folder not found in /var/lib/postgresql/data/pgdata
unit-postgresql-k8s-2: 01:42:01 ERROR unit.postgresql-k8s/2.juju-log pgdata folder not found in /var/lib/postgresql/data/pgdata
unit-postgresql-k8s-2: 01:42:27 ERROR unit.postgresql-k8s/2.juju-log pgdata folder not found in /var/lib/postgresql/data/pgdata
unit-postgresql-k8s-2: 01:42:39 ERROR unit.postgresql-k8s/2.juju-log pgdata folder not found in /var/lib/postgresql/data/pgdata
unit-postgresql-k8s-1: 01:43:16 ERROR unit.postgresql-k8s/1.juju-log failed to change plugins: 
Traceback (most recent call last):
  File "/var/lib/juju/agents/unit-postgresql-k8s-1/charm/lib/charms/postgresql_k8s/v0/postgresql.py", line 451, in enable_disable_extensions
    with self._connect_to_database(
  File "/var/lib/juju/agents/unit-postgresql-k8s-1/charm/lib/charms/tempo_coordinator_k8s/v0/charm_tracing.py", line 1109, in wrapped_function
    return callable(*args, **kwargs)  # type: ignore
  File "/var/lib/juju/agents/unit-postgresql-k8s-1/charm/lib/charms/postgresql_k8s/v0/postgresql.py", line 184, in _connect_to_database
    connection = psycopg2.connect(
  File "/var/lib/juju/agents/unit-postgresql-k8s-1/charm/venv/lib/python3.10/site-packages/psycopg2/__init__.py", line 122, in connect
    conn = _connect(dsn, connection_factory=connection_factory, **kwasync)
psycopg2.OperationalError: connection to server at "postgresql-k8s-primary.testing.svc.cluster.local" (10.152.183.142), port 5432 failed: FATAL:  no pg_hba.conf entry for host "10.1.98.18", user "operator", database "postgres", no encryption


The above exception was the direct cause of the following exception:

Traceback (most recent call last):
  File "/var/lib/juju/agents/unit-postgresql-k8s-1/charm/src/charm.py", line 797, in _handle_enable_disable_extensions
    self.postgresql.enable_disable_extensions(extensions, database)
  File "/var/lib/juju/agents/unit-postgresql-k8s-1/charm/lib/charms/tempo_coordinator_k8s/v0/charm_tracing.py", line 1109, in wrapped_function
    return callable(*args, **kwargs)  # type: ignore
  File "/var/lib/juju/agents/unit-postgresql-k8s-1/charm/lib/charms/postgresql_k8s/v0/postgresql.py", line 466, in enable_disable_extensions
    raise PostgreSQLEnableDisableExtensionError() from e
charms.postgresql_k8s.v0.postgresql.PostgreSQLEnableDisableExtensionError

[32mINFO    [0m pytest_operator.plugin:plugin.py:1025 Forgetting model main...