[32mINFO    [0m integration.test_upgrade:test_upgrade.py:158 starting continuous writes to the database
[32mINFO    [0m integration.test_upgrade:test_upgrade.py:162 checking whether writes are increasing
[32mINFO    [0m httpx:_client.py:1025 HTTP Request: GET https://10.1.0.133:16443/api/v1/namespaces/testing/pods/postgresql-k8s-0 "HTTP/1.1 200 OK"
[32mINFO    [0m httpx:_client.py:1025 HTTP Request: GET https://10.1.0.133:16443/api/v1/namespaces/testing/pods/postgresql-k8s-1 "HTTP/1.1 200 OK"
[32mINFO    [0m httpx:_client.py:1025 HTTP Request: GET https://10.1.0.133:16443/api/v1/namespaces/testing/pods/postgresql-k8s-2 "HTTP/1.1 200 OK"
[32mINFO    [0m httpx:_client.py:1025 HTTP Request: GET https://10.1.0.133:16443/api/v1/namespaces/testing/pods/postgresql-k8s-0 "HTTP/1.1 200 OK"
[32mINFO    [0m httpx:_client.py:1025 HTTP Request: GET https://10.1.0.133:16443/api/v1/namespaces/testing/pods/postgresql-k8s-1 "HTTP/1.1 200 OK"
[32mINFO    [0m httpx:_client.py:1025 HTTP Request: GET https://10.1.0.133:16443/api/v1/namespaces/testing/pods/postgresql-k8s-2 "HTTP/1.1 200 OK"
[32mINFO    [0m httpx:_client.py:1025 HTTP Request: GET https://10.1.0.133:16443/api/v1/namespaces/testing/pods/postgresql-k8s-0 "HTTP/1.1 200 OK"
[32mINFO    [0m httpx:_client.py:1025 HTTP Request: GET https://10.1.0.133:16443/api/v1/namespaces/testing/pods/postgresql-k8s-1 "HTTP/1.1 200 OK"
[32mINFO    [0m httpx:_client.py:1025 HTTP Request: GET https://10.1.0.133:16443/api/v1/namespaces/testing/pods/postgresql-k8s-2 "HTTP/1.1 200 OK"
[32mINFO    [0m httpx:_client.py:1025 HTTP Request: GET https://10.1.0.133:16443/api/v1/namespaces/testing/pods/postgresql-k8s-0 "HTTP/1.1 200 OK"
[32mINFO    [0m httpx:_client.py:1025 HTTP Request: GET https://10.1.0.133:16443/api/v1/namespaces/testing/pods/postgresql-k8s-1 "HTTP/1.1 200 OK"
[32mINFO    [0m httpx:_client.py:1025 HTTP Request: GET https://10.1.0.133:16443/api/v1/namespaces/testing/pods/postgresql-k8s-2 "HTTP/1.1 200 OK"
[32mINFO    [0m integration.test_upgrade:test_upgrade.py:165 Get leader unit
[32mINFO    [0m integration.test_upgrade:test_upgrade.py:171 Run pre-upgrade-check action
[32mINFO    [0m integration.test_upgrade:test_upgrade.py:179 Inject dependency fault
[32mINFO    [0m integration.test_upgrade:test_upgrade.py:184 Refresh the charm
[32mINFO    [0m integration.test_upgrade:test_upgrade.py:187 Get first upgrading unit
[32mINFO    [0m integration.test_upgrade:test_upgrade.py:191 Wait for upgrade to fail on first upgrading unit
[32mINFO    [0m integration.test_upgrade:test_upgrade.py:198 Ensure continuous_writes while in failure state on remaining units
[32mINFO    [0m httpx:_client.py:1025 HTTP Request: GET https://10.1.0.133:16443/api/v1/namespaces/testing/pods/postgresql-k8s-0 "HTTP/1.1 200 OK"
[32mINFO    [0m httpx:_client.py:1025 HTTP Request: GET https://10.1.0.133:16443/api/v1/namespaces/testing/pods/postgresql-k8s-1 "HTTP/1.1 200 OK"
[32mINFO    [0m httpx:_client.py:1025 HTTP Request: GET https://10.1.0.133:16443/api/v1/namespaces/testing/pods/postgresql-k8s-2 "HTTP/1.1 200 OK"
[32mINFO    [0m httpx:_client.py:1025 HTTP Request: GET https://10.1.0.133:16443/api/v1/namespaces/testing/pods/postgresql-k8s-0 "HTTP/1.1 200 OK"
[32mINFO    [0m httpx:_client.py:1025 HTTP Request: GET https://10.1.0.133:16443/api/v1/namespaces/testing/pods/postgresql-k8s-1 "HTTP/1.1 200 OK"
[32mINFO    [0m httpx:_client.py:1025 HTTP Request: GET https://10.1.0.133:16443/api/v1/namespaces/testing/pods/postgresql-k8s-2 "HTTP/1.1 200 OK"
[32mINFO    [0m httpx:_client.py:1025 HTTP Request: GET https://10.1.0.133:16443/api/v1/namespaces/testing/pods/postgresql-k8s-0 "HTTP/1.1 200 OK"
[32mINFO    [0m httpx:_client.py:1025 HTTP Request: GET https://10.1.0.133:16443/api/v1/namespaces/testing/pods/postgresql-k8s-1 "HTTP/1.1 200 OK"
[32mINFO    [0m httpx:_client.py:1025 HTTP Request: GET https://10.1.0.133:16443/api/v1/namespaces/testing/pods/postgresql-k8s-2 "HTTP/1.1 200 OK"
[32mINFO    [0m httpx:_client.py:1025 HTTP Request: GET https://10.1.0.133:16443/api/v1/namespaces/testing/pods/postgresql-k8s-0 "HTTP/1.1 200 OK"
[32mINFO    [0m httpx:_client.py:1025 HTTP Request: GET https://10.1.0.133:16443/api/v1/namespaces/testing/pods/postgresql-k8s-1 "HTTP/1.1 200 OK"
[32mINFO    [0m httpx:_client.py:1025 HTTP Request: GET https://10.1.0.133:16443/api/v1/namespaces/testing/pods/postgresql-k8s-2 "HTTP/1.1 200 OK"
[32mINFO    [0m httpx:_client.py:1025 HTTP Request: GET https://10.1.0.133:16443/api/v1/namespaces/testing/pods/postgresql-k8s-0 "HTTP/1.1 200 OK"
[32mINFO    [0m httpx:_client.py:1025 HTTP Request: GET https://10.1.0.133:16443/api/v1/namespaces/testing/pods/postgresql-k8s-1 "HTTP/1.1 200 OK"
[32mINFO    [0m httpx:_client.py:1025 HTTP Request: GET https://10.1.0.133:16443/api/v1/namespaces/testing/pods/postgresql-k8s-2 "HTTP/1.1 200 OK"
[32mINFO    [0m integration.test_upgrade:test_upgrade.py:201 Re-run pre-upgrade-check action
[32mINFO    [0m integration.test_upgrade:test_upgrade.py:205 Re-refresh the charm
[32mINFO    [0m juju.model:__init__.py:3254 Waiting for model:
  pgbouncer-k8s/0 [idle] active: 
  pgbouncer-k8s/1 [idle] blocked: ready to rollback application
  pgbouncer-k8s/2 [idle] active: 
[32mINFO    [0m juju.model:__init__.py:3254 Waiting for model:
  pgbouncer-k8s/0 [idle] waiting: other units upgrading first...
  pgbouncer-k8s/1 [idle] blocked: ready to rollback application
  pgbouncer-k8s/2 [idle] active: 
[32mINFO    [0m integration.test_upgrade:test_upgrade.py:212 Resume upgrade
[32mINFO    [0m integration.test_upgrade:test_upgrade.py:216 Wait for application to recover
[32mINFO    [0m juju.model:__init__.py:3254 Waiting for model:
  pgbouncer-k8s/0 [idle] active: 
  pgbouncer-k8s/1 [executing] maintenance: stopping charm software
  pgbouncer-k8s/2 [idle] active: 
[32mINFO    [0m juju.model:__init__.py:3254 Waiting for model:
  pgbouncer-k8s/0 [executing] maintenance: 
  pgbouncer-k8s/1 [executing] active: 
  pgbouncer-k8s/2 [executing] active: 
[32mINFO    [0m juju.model:__init__.py:3254 Waiting for model:
  pgbouncer-k8s/0 [executing] maintenance: upgrading unit
  pgbouncer-k8s/1 [executing] active: 
  pgbouncer-k8s/2 [executing] active: 
[32mINFO    [0m juju.model:__init__.py:3254 Waiting for model:
  pgbouncer-k8s/0 [idle] active: 
  pgbouncer-k8s/1 [idle] active: 
  pgbouncer-k8s/2 [idle] active: 
[32mINFO    [0m integration.test_upgrade:test_upgrade.py:220 Ensure continuous_writes after rollback procedure
[32mINFO    [0m httpx:_client.py:1025 HTTP Request: GET https://10.1.0.133:16443/api/v1/namespaces/testing/pods/postgresql-k8s-0 "HTTP/1.1 200 OK"
[32mINFO    [0m httpx:_client.py:1025 HTTP Request: GET https://10.1.0.133:16443/api/v1/namespaces/testing/pods/postgresql-k8s-1 "HTTP/1.1 200 OK"
[32mINFO    [0m httpx:_client.py:1025 HTTP Request: GET https://10.1.0.133:16443/api/v1/namespaces/testing/pods/postgresql-k8s-2 "HTTP/1.1 200 OK"
[32mINFO    [0m httpx:_client.py:1025 HTTP Request: GET https://10.1.0.133:16443/api/v1/namespaces/testing/pods/postgresql-k8s-0 "HTTP/1.1 200 OK"
[32mINFO    [0m httpx:_client.py:1025 HTTP Request: GET https://10.1.0.133:16443/api/v1/namespaces/testing/pods/postgresql-k8s-1 "HTTP/1.1 200 OK"
[32mINFO    [0m httpx:_client.py:1025 HTTP Request: GET https://10.1.0.133:16443/api/v1/namespaces/testing/pods/postgresql-k8s-2 "HTTP/1.1 200 OK"
[32mINFO    [0m httpx:_client.py:1025 HTTP Request: GET https://10.1.0.133:16443/api/v1/namespaces/testing/pods/postgresql-k8s-0 "HTTP/1.1 200 OK"
[32mINFO    [0m httpx:_client.py:1025 HTTP Request: GET https://10.1.0.133:16443/api/v1/namespaces/testing/pods/postgresql-k8s-1 "HTTP/1.1 200 OK"
[32mINFO    [0m httpx:_client.py:1025 HTTP Request: GET https://10.1.0.133:16443/api/v1/namespaces/testing/pods/postgresql-k8s-2 "HTTP/1.1 200 OK"
[32mINFO    [0m httpx:_client.py:1025 HTTP Request: GET https://10.1.0.133:16443/api/v1/namespaces/testing/pods/postgresql-k8s-0 "HTTP/1.1 200 OK"
[32mINFO    [0m httpx:_client.py:1025 HTTP Request: GET https://10.1.0.133:16443/api/v1/namespaces/testing/pods/postgresql-k8s-1 "HTTP/1.1 200 OK"
[32mINFO    [0m httpx:_client.py:1025 HTTP Request: GET https://10.1.0.133:16443/api/v1/namespaces/testing/pods/postgresql-k8s-2 "HTTP/1.1 200 OK"
[32mINFO    [0m integration.test_upgrade:test_upgrade.py:225 Checking whether no writes were lost
[32mINFO    [0m httpx:_client.py:1025 HTTP Request: GET https://10.1.0.133:16443/api/v1/namespaces/testing/pods/postgresql-k8s-0 "HTTP/1.1 200 OK"
[32mINFO    [0m httpx:_client.py:1025 HTTP Request: GET https://10.1.0.133:16443/api/v1/namespaces/testing/pods/postgresql-k8s-1 "HTTP/1.1 200 OK"
[32mINFO    [0m httpx:_client.py:1025 HTTP Request: GET https://10.1.0.133:16443/api/v1/namespaces/testing/pods/postgresql-k8s-2 "HTTP/1.1 200 OK"
[32mINFO    [0m pytest_operator.plugin:plugin.py:936 Model status:

Model    Controller          Cloud/Region        Version  SLA          Timestamp
testing  concierge-microk8s  microk8s/localhost  3.6.2    unsupported  01:58:00Z

App                  Version  Status  Scale  Charm                Channel      Rev  Address        Exposed  Message
pgbouncer-k8s        1.21.0   active      3  pgbouncer-k8s                       2  10.152.183.27  no       
postgresql-k8s       14.15    active      3  postgresql-k8s       14/edge      507  10.152.183.99  no       
postgresql-test-app           active      1  postgresql-test-app  latest/edge  360  10.152.183.23  no       received database credentials of the first database

Unit                    Workload  Agent  Address      Ports  Message
pgbouncer-k8s/0         active    idle   10.1.195.25         
pgbouncer-k8s/1*        active    idle   10.1.195.24         
pgbouncer-k8s/2         active    idle   10.1.195.23         
postgresql-k8s/0*       active    idle   10.1.195.16         Primary
postgresql-k8s/1        active    idle   10.1.195.18         
postgresql-k8s/2        active    idle   10.1.195.17         
postgresql-test-app/0*  active    idle   10.1.195.9          received database credentials of the first database

[32mINFO    [0m pytest_operator.plugin:plugin.py:942 Juju error logs:

unit-postgresql-k8s-2: 01:45:49 ERROR unit.postgresql-k8s/2.juju-log Uncaught exception while in charm code:
Traceback (most recent call last):
  File "/var/lib/juju/agents/unit-postgresql-k8s-2/charm/venv/lib/python3.10/site-packages/ops/model.py", line 3320, in _run
    result = subprocess.run(args, **kwargs)  # type: ignore
  File "/usr/lib/python3.10/subprocess.py", line 526, in run
    raise CalledProcessError(retcode, process.args,
subprocess.CalledProcessError: Command '('/var/lib/juju/tools/unit-postgresql-k8s-2/secret-get', '--label', 'database-peers.postgresql-k8s.app', '--format=json')' returned non-zero exit status 1.

The above exception was the direct cause of the following exception:

Traceback (most recent call last):
  File "/var/lib/juju/agents/unit-postgresql-k8s-2/charm/src/charm.py", line 2311, in <module>
    main(PostgresqlOperatorCharm, use_juju_for_storage=True)
  File "/var/lib/juju/agents/unit-postgresql-k8s-2/charm/venv/lib/python3.10/site-packages/ops/__init__.py", line 343, in __call__
    return _main.main(charm_class=charm_class, use_juju_for_storage=use_juju_for_storage)
  File "/var/lib/juju/agents/unit-postgresql-k8s-2/charm/venv/lib/python3.10/site-packages/ops/_main.py", line 558, in main
    manager.run()
  File "/var/lib/juju/agents/unit-postgresql-k8s-2/charm/venv/lib/python3.10/site-packages/ops/_main.py", line 543, in run
    self._emit()
  File "/var/lib/juju/agents/unit-postgresql-k8s-2/charm/venv/lib/python3.10/site-packages/ops/_main.py", line 502, in _emit
    self._emit_charm_event(self.dispatcher.event_name)
  File "/var/lib/juju/agents/unit-postgresql-k8s-2/charm/venv/lib/python3.10/site-packages/ops/_main.py", line 530, in _emit_charm_event
    event_to_emit.emit(*args, **kwargs)
  File "/var/lib/juju/agents/unit-postgresql-k8s-2/charm/venv/lib/python3.10/site-packages/ops/framework.py", line 347, in emit
    framework._emit(event)
  File "/var/lib/juju/agents/unit-postgresql-k8s-2/charm/venv/lib/python3.10/site-packages/ops/framework.py", line 906, in _emit
    self._reemit(event_path)
  File "/var/lib/juju/agents/unit-postgresql-k8s-2/charm/venv/lib/python3.10/site-packages/ops/framework.py", line 996, in _reemit
    custom_handler(event)
  File "/var/lib/juju/agents/unit-postgresql-k8s-2/charm/lib/charms/tempo_coordinator_k8s/v0/charm_tracing.py", line 1106, in wrapped_function
    return callable(*args, **kwargs)  # type: ignore
  File "/var/lib/juju/agents/unit-postgresql-k8s-2/charm/src/charm.py", line 976, in _on_postgresql_pebble_ready
    self.unit.set_workload_version(self._patroni.rock_postgresql_version)
  File "/var/lib/juju/agents/unit-postgresql-k8s-2/charm/src/charm.py", line 1630, in _patroni
    self.get_secret(APP_SCOPE, USER_PASSWORD_KEY),
  File "/var/lib/juju/agents/unit-postgresql-k8s-2/charm/lib/charms/tempo_coordinator_k8s/v0/charm_tracing.py", line 1106, in wrapped_function
    return callable(*args, **kwargs)  # type: ignore
  File "/var/lib/juju/agents/unit-postgresql-k8s-2/charm/src/charm.py", line 358, in get_secret
    return self.peer_relation_data(scope).get_secret(peers.id, secret_key)
  File "/var/lib/juju/agents/unit-postgresql-k8s-2/charm/lib/charms/data_platform_libs/v0/data_interfaces.py", line 521, in wrapper
    return f(self, *args, **kwargs)
  File "/var/lib/juju/agents/unit-postgresql-k8s-2/charm/lib/charms/data_platform_libs/v0/data_interfaces.py", line 2043, in get_secret
    and full_field not in self.current_secret_fields
  File "/var/lib/juju/agents/unit-postgresql-k8s-2/charm/lib/charms/data_platform_libs/v0/data_interfaces.py", line 2000, in current_secret_fields
    if content := self._get_group_secret_contents(relation, group):
  File "/var/lib/juju/agents/unit-postgresql-k8s-2/charm/lib/charms/data_platform_libs/v0/data_interfaces.py", line 2331, in _get_group_secret_contents
    result = super()._get_group_secret_contents(relation, group, secret_fields)
  File "/var/lib/juju/agents/unit-postgresql-k8s-2/charm/lib/charms/data_platform_libs/v0/data_interfaces.py", line 1123, in _get_group_secret_contents
    if (secret := self._get_relation_secret(relation.id, group)) and (
  File "/var/lib/juju/agents/unit-postgresql-k8s-2/charm/lib/charms/data_platform_libs/v0/data_interfaces.py", line 508, in wrapper
    return f(self, *args, **kwargs)
  File "/var/lib/juju/agents/unit-postgresql-k8s-2/charm/lib/charms/data_platform_libs/v0/data_interfaces.py", line 2318, in _get_relation_secret
    return self.secrets.get(
  File "/var/lib/juju/agents/unit-postgresql-k8s-2/charm/lib/charms/data_platform_libs/v0/data_interfaces.py", line 812, in get
    if secret.meta:
  File "/var/lib/juju/agents/unit-postgresql-k8s-2/charm/lib/charms/data_platform_libs/v0/data_interfaces.py", line 642, in meta
    self._secret_meta = self._model.get_secret(label=self.label)
  File "/var/lib/juju/agents/unit-postgresql-k8s-2/charm/venv/lib/python3.10/site-packages/ops/model.py", line 308, in get_secret
    content = self._backend.secret_get(id=id, label=label)
  File "/var/lib/juju/agents/unit-postgresql-k8s-2/charm/venv/lib/python3.10/site-packages/ops/model.py", line 3692, in secret_get
    result = self._run('secret-get', *args, return_output=True, use_json=True)
  File "/var/lib/juju/agents/unit-postgresql-k8s-2/charm/venv/lib/python3.10/site-packages/ops/model.py", line 3322, in _run
    raise ModelError(e.stderr) from e
ops.model.ModelError: ERROR permission denied

unit-postgresql-k8s-1: 01:45:49 ERROR unit.postgresql-k8s/1.juju-log Uncaught exception while in charm code:
Traceback (most recent call last):
  File "/var/lib/juju/agents/unit-postgresql-k8s-1/charm/venv/lib/python3.10/site-packages/ops/model.py", line 3320, in _run
    result = subprocess.run(args, **kwargs)  # type: ignore
  File "/usr/lib/python3.10/subprocess.py", line 526, in run
    raise CalledProcessError(retcode, process.args,
subprocess.CalledProcessError: Command '('/var/lib/juju/tools/unit-postgresql-k8s-1/secret-get', '--label', 'database-peers.postgresql-k8s.app', '--format=json')' returned non-zero exit status 1.

The above exception was the direct cause of the following exception:

Traceback (most recent call last):
  File "/var/lib/juju/agents/unit-postgresql-k8s-1/charm/src/charm.py", line 2311, in <module>
    main(PostgresqlOperatorCharm, use_juju_for_storage=True)
  File "/var/lib/juju/agents/unit-postgresql-k8s-1/charm/venv/lib/python3.10/site-packages/ops/__init__.py", line 343, in __call__
    return _main.main(charm_class=charm_class, use_juju_for_storage=use_juju_for_storage)
  File "/var/lib/juju/agents/unit-postgresql-k8s-1/charm/venv/lib/python3.10/site-packages/ops/_main.py", line 558, in main
    manager.run()
  File "/var/lib/juju/agents/unit-postgresql-k8s-1/charm/venv/lib/python3.10/site-packages/ops/_main.py", line 543, in run
    self._emit()
  File "/var/lib/juju/agents/unit-postgresql-k8s-1/charm/venv/lib/python3.10/site-packages/ops/_main.py", line 502, in _emit
    self._emit_charm_event(self.dispatcher.event_name)
  File "/var/lib/juju/agents/unit-postgresql-k8s-1/charm/venv/lib/python3.10/site-packages/ops/_main.py", line 530, in _emit_charm_event
    event_to_emit.emit(*args, **kwargs)
  File "/var/lib/juju/agents/unit-postgresql-k8s-1/charm/venv/lib/python3.10/site-packages/ops/framework.py", line 347, in emit
    framework._emit(event)
  File "/var/lib/juju/agents/unit-postgresql-k8s-1/charm/venv/lib/python3.10/site-packages/ops/framework.py", line 906, in _emit
    self._reemit(event_path)
  File "/var/lib/juju/agents/unit-postgresql-k8s-1/charm/venv/lib/python3.10/site-packages/ops/framework.py", line 996, in _reemit
    custom_handler(event)
  File "/var/lib/juju/agents/unit-postgresql-k8s-1/charm/lib/charms/tempo_coordinator_k8s/v0/charm_tracing.py", line 1106, in wrapped_function
    return callable(*args, **kwargs)  # type: ignore
  File "/var/lib/juju/agents/unit-postgresql-k8s-1/charm/src/charm.py", line 976, in _on_postgresql_pebble_ready
    self.unit.set_workload_version(self._patroni.rock_postgresql_version)
  File "/var/lib/juju/agents/unit-postgresql-k8s-1/charm/src/charm.py", line 1630, in _patroni
    self.get_secret(APP_SCOPE, USER_PASSWORD_KEY),
  File "/var/lib/juju/agents/unit-postgresql-k8s-1/charm/lib/charms/tempo_coordinator_k8s/v0/charm_tracing.py", line 1106, in wrapped_function
    return callable(*args, **kwargs)  # type: ignore
  File "/var/lib/juju/agents/unit-postgresql-k8s-1/charm/src/charm.py", line 358, in get_secret
    return self.peer_relation_data(scope).get_secret(peers.id, secret_key)
  File "/var/lib/juju/agents/unit-postgresql-k8s-1/charm/lib/charms/data_platform_libs/v0/data_interfaces.py", line 521, in wrapper
    return f(self, *args, **kwargs)
  File "/var/lib/juju/agents/unit-postgresql-k8s-1/charm/lib/charms/data_platform_libs/v0/data_interfaces.py", line 2044, in get_secret
    and field not in self.current_secret_fields
  File "/var/lib/juju/agents/unit-postgresql-k8s-1/charm/lib/charms/data_platform_libs/v0/data_interfaces.py", line 2000, in current_secret_fields
    if content := self._get_group_secret_contents(relation, group):
  File "/var/lib/juju/agents/unit-postgresql-k8s-1/charm/lib/charms/data_platform_libs/v0/data_interfaces.py", line 2331, in _get_group_secret_contents
    result = super()._get_group_secret_contents(relation, group, secret_fields)
  File "/var/lib/juju/agents/unit-postgresql-k8s-1/charm/lib/charms/data_platform_libs/v0/data_interfaces.py", line 1123, in _get_group_secret_contents
    if (secret := self._get_relation_secret(relation.id, group)) and (
  File "/var/lib/juju/agents/unit-postgresql-k8s-1/charm/lib/charms/data_platform_libs/v0/data_interfaces.py", line 508, in wrapper
    return f(self, *args, **kwargs)
  File "/var/lib/juju/agents/unit-postgresql-k8s-1/charm/lib/charms/data_platform_libs/v0/data_interfaces.py", line 2318, in _get_relation_secret
    return self.secrets.get(
  File "/var/lib/juju/agents/unit-postgresql-k8s-1/charm/lib/charms/data_platform_libs/v0/data_interfaces.py", line 812, in get
    if secret.meta:
  File "/var/lib/juju/agents/unit-postgresql-k8s-1/charm/lib/charms/data_platform_libs/v0/data_interfaces.py", line 642, in meta
    self._secret_meta = self._model.get_secret(label=self.label)
  File "/var/lib/juju/agents/unit-postgresql-k8s-1/charm/venv/lib/python3.10/site-packages/ops/model.py", line 308, in get_secret
    content = self._backend.secret_get(id=id, label=label)
  File "/var/lib/juju/agents/unit-postgresql-k8s-1/charm/venv/lib/python3.10/site-packages/ops/model.py", line 3692, in secret_get
    result = self._run('secret-get', *args, return_output=True, use_json=True)
  File "/var/lib/juju/agents/unit-postgresql-k8s-1/charm/venv/lib/python3.10/site-packages/ops/model.py", line 3322, in _run
    raise ModelError(e.stderr) from e
ops.model.ModelError: ERROR permission denied

unit-postgresql-k8s-1: 01:45:49 ERROR juju.worker.uniter.operation hook "postgresql-pebble-ready" (via hook dispatching script: dispatch) failed: exit status 1
unit-postgresql-k8s-1: 01:45:49 ERROR juju.worker.uniter pebble poll failed for container "postgresql": failed to send pebble-ready event: hook failed
unit-postgresql-k8s-2: 01:45:49 ERROR juju.worker.uniter.operation hook "postgresql-pebble-ready" (via hook dispatching script: dispatch) failed: exit status 1
unit-postgresql-k8s-2: 01:45:49 ERROR juju.worker.uniter pebble poll failed for container "postgresql": failed to send pebble-ready event: hook failed
unit-postgresql-k8s-2: 01:48:02 ERROR unit.postgresql-k8s/2.juju-log pgdata folder not found in /var/lib/postgresql/data/pgdata
unit-pgbouncer-k8s-2: 01:51:32 ERROR unit.pgbouncer-k8s/2.juju-log pgbouncer not running
unit-pgbouncer-k8s-2: 01:51:34 ERROR unit.pgbouncer-k8s/2.juju-log pgbouncer not running
unit-pgbouncer-k8s-2: 01:51:35 ERROR unit.pgbouncer-k8s/2.juju-log pgbouncer not running
unit-pgbouncer-k8s-2: 01:51:36 ERROR unit.pgbouncer-k8s/2.juju-log pgbouncer not running
unit-pgbouncer-k8s-1: 01:52:31 ERROR unit.pgbouncer-k8s/1.juju-log pgbouncer not running
unit-pgbouncer-k8s-0: 01:52:56 ERROR unit.pgbouncer-k8s/0.juju-log pgbouncer not running
unit-pgbouncer-k8s-0: 01:52:58 ERROR unit.pgbouncer-k8s/0.juju-log pgbouncer not running
unit-pgbouncer-k8s-0: 01:52:59 ERROR unit.pgbouncer-k8s/0.juju-log pgbouncer not running
unit-pgbouncer-k8s-0: 01:53:01 ERROR unit.pgbouncer-k8s/0.juju-log pgbouncer not running
unit-pgbouncer-k8s-0: 01:53:02 ERROR unit.pgbouncer-k8s/0.juju-log Uncaught exception while in charm code:
Traceback (most recent call last):
  File "/var/lib/juju/agents/unit-pgbouncer-k8s-0/charm/src/charm.py", line 1138, in <module>
    main(PgBouncerK8sCharm)
  File "/var/lib/juju/agents/unit-pgbouncer-k8s-0/charm/venv/lib/python3.10/site-packages/ops/__init__.py", line 343, in __call__
    return _main.main(charm_class=charm_class, use_juju_for_storage=use_juju_for_storage)
  File "/var/lib/juju/agents/unit-pgbouncer-k8s-0/charm/venv/lib/python3.10/site-packages/ops/_main.py", line 558, in main
    manager.run()
  File "/var/lib/juju/agents/unit-pgbouncer-k8s-0/charm/venv/lib/python3.10/site-packages/ops/_main.py", line 543, in run
    self._emit()
  File "/var/lib/juju/agents/unit-pgbouncer-k8s-0/charm/venv/lib/python3.10/site-packages/ops/_main.py", line 502, in _emit
    self._emit_charm_event(self.dispatcher.event_name)
  File "/var/lib/juju/agents/unit-pgbouncer-k8s-0/charm/venv/lib/python3.10/site-packages/ops/_main.py", line 530, in _emit_charm_event
    event_to_emit.emit(*args, **kwargs)
  File "/var/lib/juju/agents/unit-pgbouncer-k8s-0/charm/venv/lib/python3.10/site-packages/ops/framework.py", line 347, in emit
    framework._emit(event)
  File "/var/lib/juju/agents/unit-pgbouncer-k8s-0/charm/venv/lib/python3.10/site-packages/ops/framework.py", line 906, in _emit
    self._reemit(event_path)
  File "/var/lib/juju/agents/unit-pgbouncer-k8s-0/charm/venv/lib/python3.10/site-packages/ops/framework.py", line 996, in _reemit
    custom_handler(event)
  File "/var/lib/juju/agents/unit-pgbouncer-k8s-0/charm/lib/charms/tempo_coordinator_k8s/v0/charm_tracing.py", line 1106, in wrapped_function
    return callable(*args, **kwargs)  # type: ignore
  File "/var/lib/juju/agents/unit-pgbouncer-k8s-0/charm/src/charm.py", line 365, in _on_pgbouncer_pebble_ready
    container.replan()
  File "/var/lib/juju/agents/unit-pgbouncer-k8s-0/charm/venv/lib/python3.10/site-packages/ops/model.py", line 2381, in replan
    self._pebble.replan_services()
  File "/var/lib/juju/agents/unit-pgbouncer-k8s-0/charm/venv/lib/python3.10/site-packages/ops/pebble.py", line 2144, in replan_services
    return self._services_action('replan', [], timeout, delay)
  File "/var/lib/juju/agents/unit-pgbouncer-k8s-0/charm/venv/lib/python3.10/site-packages/ops/pebble.py", line 2244, in _services_action
    raise ChangeError(change.err, change)
ops.pebble.ChangeError: cannot perform the following tasks:
- Start service "metrics_server" (service start attempt: exited quickly with code 1, will restart)
----- Logs from task 5 -----
2025-02-21T01:53:01Z INFO Most recent service output:
    ts=2025-02-21T01:53:01.387Z caller=collector.go:138 level=error msg="error setting up DB connection" err="error pinging pgbouncer: dial tcp [::1]:6432: connect: connection refused"
2025-02-21T01:53:01Z ERROR service start attempt: exited quickly with code 1, will restart
-----
unit-pgbouncer-k8s-0: 01:53:02 ERROR juju.worker.uniter.operation hook "pgbouncer-pebble-ready" (via hook dispatching script: dispatch) failed: exit status 1
unit-pgbouncer-k8s-0: 01:53:02 ERROR juju.worker.uniter pebble poll failed for container "pgbouncer": failed to send pebble-ready event: hook failed
unit-pgbouncer-k8s-2: 01:54:47 ERROR unit.pgbouncer-k8s/2.juju-log charms.data_platform_libs.v0.upgrade.VersionError - {'message': 'Versions incompatible, charm 1 can not be upgraded to 15.0', 'cause': 'Upgrades only supported for specific versions, charm versions satisfying requirement ^15', 'resolution': ''}
unit-pgbouncer-k8s-2: 01:54:49 ERROR unit.pgbouncer-k8s/2.juju-log pgbouncer not running
unit-pgbouncer-k8s-2: 01:54:52 ERROR unit.pgbouncer-k8s/2.juju-log pgbouncer not running
unit-pgbouncer-k8s-2: 01:54:53 ERROR unit.pgbouncer-k8s/2.juju-log pgbouncer not running
unit-pgbouncer-k8s-2: 01:54:54 ERROR unit.pgbouncer-k8s/2.juju-log pgbouncer not running
unit-pgbouncer-k8s-2: 01:55:25 ERROR unit.pgbouncer-k8s/2.juju-log pgbouncer not running
unit-pgbouncer-k8s-2: 01:55:27 ERROR unit.pgbouncer-k8s/2.juju-log pgbouncer not running
unit-pgbouncer-k8s-2: 01:55:28 ERROR unit.pgbouncer-k8s/2.juju-log pgbouncer not running
unit-pgbouncer-k8s-2: 01:55:29 ERROR unit.pgbouncer-k8s/2.juju-log pgbouncer not running
unit-pgbouncer-k8s-0: 01:57:09 ERROR unit.pgbouncer-k8s/0.juju-log pgbouncer not running
unit-pgbouncer-k8s-0: 01:57:11 ERROR unit.pgbouncer-k8s/0.juju-log pgbouncer not running
unit-pgbouncer-k8s-0: 01:57:12 ERROR unit.pgbouncer-k8s/0.juju-log pgbouncer not running
unit-pgbouncer-k8s-0: 01:57:14 ERROR unit.pgbouncer-k8s/0.juju-log pgbouncer not running

[32mINFO    [0m pytest_operator.plugin:plugin.py:1024 Forgetting model main...