[32mINFO    [0m pytest_operator.plugin:plugin.py:937 Model status:

Model    Controller          Cloud/Region        Version  SLA          Timestamp
testing  concierge-microk8s  microk8s/localhost  3.6.8    unsupported  01:43:43Z

App                  Version  Status   Scale  Charm                Channel      Rev  Address         Exposed  Message
pgbouncer-k8s        1.21.0   blocked      3  pgbouncer-k8s        1/edge       469  10.152.183.155  no       waiting for backend database relation to initialise
postgresql-k8s       14.18    error        3  postgresql-k8s       14/edge      616  10.152.183.19   no       hook failed: "storage-attached"
postgresql-test-app           active       1  postgresql-test-app  latest/edge  389  10.152.183.181  no       

Unit                    Workload     Agent      Address     Ports  Message
pgbouncer-k8s/0*        waiting      executing  10.1.32.74         waiting for backend-database relation to connect
pgbouncer-k8s/1         blocked      executing  10.1.32.76         waiting for backend database relation to initialise
pgbouncer-k8s/2         blocked      executing  10.1.32.75         waiting for backend database relation to initialise
postgresql-k8s/0*       waiting      executing  10.1.32.80         awaiting for cluster to start
postgresql-k8s/1        maintenance  executing  10.1.32.82         (start) installing charm software
postgresql-k8s/2        error        idle       10.1.32.81         hook failed: "storage-attached"
postgresql-test-app/0*  active       idle       10.1.32.73         

[32mINFO    [0m pytest_operator.plugin:plugin.py:943 Juju error logs:

unit-postgresql-k8s-2: 01:43:41 ERROR unit.postgresql-k8s/2.juju-log Uncaught exception while in charm code:
Traceback (most recent call last):
  File "/var/lib/juju/agents/unit-postgresql-k8s-2/charm/venv/lib/python3.10/site-packages/websocket/_socket.py", line 118, in recv
    bytes_ = _recv()
  File "/var/lib/juju/agents/unit-postgresql-k8s-2/charm/venv/lib/python3.10/site-packages/websocket/_socket.py", line 97, in _recv
    return sock.recv(bufsize)
TimeoutError: timed out

During handling of the above exception, another exception occurred:

Traceback (most recent call last):
  File "/var/lib/juju/agents/unit-postgresql-k8s-2/charm/venv/lib/python3.10/site-packages/ops/pebble.py", line 3096, in exec
    control_ws = self._connect_websocket(task_id, 'control')
  File "/var/lib/juju/agents/unit-postgresql-k8s-2/charm/venv/lib/python3.10/site-packages/ops/pebble.py", line 3188, in _connect_websocket
    ws.connect(url, socket=sock)
  File "/var/lib/juju/agents/unit-postgresql-k8s-2/charm/venv/lib/python3.10/site-packages/websocket/_core.py", line 261, in connect
    self.handshake_response = handshake(self.sock, url, *addrs, **options)
  File "/var/lib/juju/agents/unit-postgresql-k8s-2/charm/venv/lib/python3.10/site-packages/websocket/_handshake.py", line 65, in handshake
    status, resp = _get_resp_headers(sock)
  File "/var/lib/juju/agents/unit-postgresql-k8s-2/charm/venv/lib/python3.10/site-packages/websocket/_handshake.py", line 141, in _get_resp_headers
    status, resp_headers, status_message = read_headers(sock)
  File "/var/lib/juju/agents/unit-postgresql-k8s-2/charm/venv/lib/python3.10/site-packages/websocket/_http.py", line 351, in read_headers
    line = recv_line(sock)
  File "/var/lib/juju/agents/unit-postgresql-k8s-2/charm/venv/lib/python3.10/site-packages/websocket/_socket.py", line 140, in recv_line
    c = recv(sock, 1)
  File "/var/lib/juju/agents/unit-postgresql-k8s-2/charm/venv/lib/python3.10/site-packages/websocket/_socket.py", line 120, in recv
    raise WebSocketTimeoutException("Connection timed out")
websocket._exceptions.WebSocketTimeoutException: Connection timed out

The above exception was the direct cause of the following exception:

Traceback (most recent call last):
  File "/var/lib/juju/agents/unit-postgresql-k8s-2/charm/src/charm.py", line 2520, in <module>
    main(PostgresqlOperatorCharm, use_juju_for_storage=True)
  File "/var/lib/juju/agents/unit-postgresql-k8s-2/charm/venv/lib/python3.10/site-packages/ops/__init__.py", line 356, in __call__
    return _main.main(charm_class=charm_class, use_juju_for_storage=use_juju_for_storage)
  File "/var/lib/juju/agents/unit-postgresql-k8s-2/charm/venv/lib/python3.10/site-packages/ops/_main.py", line 475, in main
    manager.run()
  File "/var/lib/juju/agents/unit-postgresql-k8s-2/charm/venv/lib/python3.10/site-packages/ops/_main.py", line 459, in run
    self._emit()
  File "/var/lib/juju/agents/unit-postgresql-k8s-2/charm/venv/lib/python3.10/site-packages/ops/_main.py", line 400, in _emit
    self.framework.reemit()
  File "/var/lib/juju/agents/unit-postgresql-k8s-2/charm/venv/lib/python3.10/site-packages/ops/framework.py", line 934, in reemit
    self._reemit()
  File "/var/lib/juju/agents/unit-postgresql-k8s-2/charm/venv/lib/python3.10/site-packages/ops/framework.py", line 1030, in _reemit
    custom_handler(event)
  File "/var/lib/juju/agents/unit-postgresql-k8s-2/charm/lib/charms/tempo_coordinator_k8s/v0/charm_tracing.py", line 1109, in wrapped_function
    return callable(*args, **kwargs)  # type: ignore
  File "/var/lib/juju/agents/unit-postgresql-k8s-2/charm/src/charm.py", line 1005, in _on_postgresql_pebble_ready
    self._create_pgdata(container)
  File "/var/lib/juju/agents/unit-postgresql-k8s-2/charm/lib/charms/tempo_coordinator_k8s/v0/charm_tracing.py", line 1109, in wrapped_function
    return callable(*args, **kwargs)  # type: ignore
  File "/var/lib/juju/agents/unit-postgresql-k8s-2/charm/src/charm.py", line 981, in _create_pgdata
    container.exec([
  File "/var/lib/juju/agents/unit-postgresql-k8s-2/charm/venv/lib/python3.10/site-packages/ops/model.py", line 3074, in exec
    return self._pebble.exec(
  File "/var/lib/juju/agents/unit-postgresql-k8s-2/charm/venv/lib/python3.10/site-packages/ops/pebble.py", line 3105, in exec
    raise ChangeError(change.err, change) from e
ops.pebble.ChangeError: cannot perform the following tasks:
- Execute command "chown" (exec 2: timeout waiting for websocket connections: context deadline exceeded)
----- Logs from task 0 -----
2025-07-08T01:43:41Z ERROR exec 2: timeout waiting for websocket connections: context deadline exceeded
-----
unit-postgresql-k8s-2: 01:43:42 ERROR juju.worker.uniter.operation hook "pgdata-storage-attached" (via hook dispatching script: dispatch) failed: exit status 1

[32mINFO    [0m pytest_operator.plugin:plugin.py:1025 Forgetting model main...