[32mINFO    [0m juju.model:model.py:2972 Waiting for model:
  postgresql-k8s/0 [idle] active: 
  postgresql-k8s/1 [idle] active: 
  postgresql-k8s/2 [idle] active: Primary
  pgbouncer-k8s/0 [executing] active: 
  pgbouncer-k8s/1 [executing] active: 
[32mINFO    [0m juju.model:model.py:2972 Waiting for model:
  pgbouncer-k8s/0 [idle] active: 
  pgbouncer-k8s/1 [idle] active: 
[32mINFO    [0m juju.model:model.py:2972 Waiting for model:
  pgbouncer-k8s/0 [idle] active: 
  pgbouncer-k8s/1 [idle] active: 
[32mINFO    [0m juju.model:model.py:2972 Waiting for model:
  pgbouncer-k8s/1 [idle] blocked: waiting for backend database relation to initialise
[32mINFO    [0m pytest_operator.plugin:plugin.py:903 Model status:

Model  Controller          Cloud/Region        Version  SLA          Timestamp
test   microk8s-localhost  microk8s/localhost  3.4.6    unsupported  01:43:36Z

App             Version  Status   Scale  Charm           Channel  Rev  Address         Exposed  Message
pgbouncer-k8s   1.21.0   waiting      2  pgbouncer-k8s              0  10.152.183.253  no       installing agent
postgresql-k8s  14.13    active     1/0  postgresql-k8s  14/edge  416  10.152.183.237  no       

Unit               Workload     Agent      Address      Ports  Message
pgbouncer-k8s/0*   blocked      idle       10.1.212.72         waiting for backend database relation to initialise
pgbouncer-k8s/1    blocked      idle       10.1.212.73         waiting for backend database relation to initialise
postgresql-k8s/0   terminated   executing  10.1.212.79         (remove) 
postgresql-k8s/1   terminated   executing  10.1.212.80         (remove) 
postgresql-k8s/2*  maintenance  executing  10.1.212.81         (remove) cleaning up prior to charm deletion

[32mINFO    [0m pytest_operator.plugin:plugin.py:909 Juju error logs:

controller-0: 01:42:09 ERROR juju.worker.caasapplicationprovisioner.runner exited "finos-waltz": getting OCI image resources: unable to fetch OCI image resources for finos-waltz: application "finos-waltz" dying or dead
unit-postgresql-k8s-2: 01:43:03 ERROR juju.worker.dependency "uniter" manifold worker returned unexpected error: relation scope id "f0479be4-e6cf-4eef-8fae-1eb28740cb32:r#5#pgbouncer-k8s": settings f0479be4-e6cf-4eef-8fae-1eb28740cb32:r#5#pgbouncer-k8s not found (not found)
unit-postgresql-k8s-0: 01:43:05 ERROR juju.worker.dependency "uniter" manifold worker returned unexpected error: relation scope id "f0479be4-e6cf-4eef-8fae-1eb28740cb32:r#5#pgbouncer-k8s": settings f0479be4-e6cf-4eef-8fae-1eb28740cb32:r#5#pgbouncer-k8s not found (not found)
unit-postgresql-k8s-1: 01:43:05 ERROR juju.worker.dependency "uniter" manifold worker returned unexpected error: relation scope id "f0479be4-e6cf-4eef-8fae-1eb28740cb32:r#5#pgbouncer-k8s": settings f0479be4-e6cf-4eef-8fae-1eb28740cb32:r#5#pgbouncer-k8s not found (not found)
unit-postgresql-k8s-0: 01:43:15 ERROR unit.postgresql-k8s/0.juju-log Uncaught exception while in charm code:
Traceback (most recent call last):
  File "/var/lib/juju/agents/unit-postgresql-k8s-0/charm/./src/charm.py", line 2202, in <module>
    main(PostgresqlOperatorCharm, use_juju_for_storage=True)
  File "/var/lib/juju/agents/unit-postgresql-k8s-0/charm/venv/ops/__init__.py", line 343, in __call__
    return _main.main(charm_class=charm_class, use_juju_for_storage=use_juju_for_storage)
  File "/var/lib/juju/agents/unit-postgresql-k8s-0/charm/venv/ops/_main.py", line 543, in main
    manager.run()
  File "/var/lib/juju/agents/unit-postgresql-k8s-0/charm/venv/ops/_main.py", line 529, in run
    self._emit()
  File "/var/lib/juju/agents/unit-postgresql-k8s-0/charm/venv/ops/_main.py", line 518, in _emit
    _emit_charm_event(self.charm, self.dispatcher.event_name, self._juju_context)
  File "/var/lib/juju/agents/unit-postgresql-k8s-0/charm/venv/ops/_main.py", line 134, in _emit_charm_event
    event_to_emit.emit(*args, **kwargs)
  File "/var/lib/juju/agents/unit-postgresql-k8s-0/charm/venv/ops/framework.py", line 347, in emit
    framework._emit(event)
  File "/var/lib/juju/agents/unit-postgresql-k8s-0/charm/venv/ops/framework.py", line 857, in _emit
    self._reemit(event_path)
  File "/var/lib/juju/agents/unit-postgresql-k8s-0/charm/venv/ops/framework.py", line 947, in _reemit
    custom_handler(event)
  File "/var/lib/juju/agents/unit-postgresql-k8s-0/charm/lib/charms/tempo_coordinator_k8s/v0/charm_tracing.py", line 734, in wrapped_function
    return callable(*args, **kwargs)  # type: ignore
  File "/var/lib/juju/agents/unit-postgresql-k8s-0/charm/./src/charm.py", line 923, in _on_postgresql_pebble_ready
    if not self.unit.is_leader() and "cluster_initialised" not in self._peers.data[self.app]:
AttributeError: 'NoneType' object has no attribute 'data'
unit-postgresql-k8s-0: 01:43:15 ERROR juju.worker.uniter.operation hook "postgresql-pebble-ready" (via hook dispatching script: dispatch) failed: exit status 1
unit-postgresql-k8s-0: 01:43:15 ERROR juju.worker.uniter pebble poll failed for container "postgresql": failed to send pebble-ready event: hook failed
unit-postgresql-k8s-1: 01:43:15 ERROR unit.postgresql-k8s/1.juju-log Uncaught exception while in charm code:
Traceback (most recent call last):
  File "/var/lib/juju/agents/unit-postgresql-k8s-1/charm/./src/charm.py", line 2202, in <module>
    main(PostgresqlOperatorCharm, use_juju_for_storage=True)
  File "/var/lib/juju/agents/unit-postgresql-k8s-1/charm/venv/ops/__init__.py", line 343, in __call__
    return _main.main(charm_class=charm_class, use_juju_for_storage=use_juju_for_storage)
  File "/var/lib/juju/agents/unit-postgresql-k8s-1/charm/venv/ops/_main.py", line 543, in main
    manager.run()
  File "/var/lib/juju/agents/unit-postgresql-k8s-1/charm/venv/ops/_main.py", line 529, in run
    self._emit()
  File "/var/lib/juju/agents/unit-postgresql-k8s-1/charm/venv/ops/_main.py", line 518, in _emit
    _emit_charm_event(self.charm, self.dispatcher.event_name, self._juju_context)
  File "/var/lib/juju/agents/unit-postgresql-k8s-1/charm/venv/ops/_main.py", line 134, in _emit_charm_event
    event_to_emit.emit(*args, **kwargs)
  File "/var/lib/juju/agents/unit-postgresql-k8s-1/charm/venv/ops/framework.py", line 347, in emit
    framework._emit(event)
  File "/var/lib/juju/agents/unit-postgresql-k8s-1/charm/venv/ops/framework.py", line 857, in _emit
    self._reemit(event_path)
  File "/var/lib/juju/agents/unit-postgresql-k8s-1/charm/venv/ops/framework.py", line 947, in _reemit
    custom_handler(event)
  File "/var/lib/juju/agents/unit-postgresql-k8s-1/charm/lib/charms/tempo_coordinator_k8s/v0/charm_tracing.py", line 734, in wrapped_function
    return callable(*args, **kwargs)  # type: ignore
  File "/var/lib/juju/agents/unit-postgresql-k8s-1/charm/./src/charm.py", line 923, in _on_postgresql_pebble_ready
    if not self.unit.is_leader() and "cluster_initialised" not in self._peers.data[self.app]:
AttributeError: 'NoneType' object has no attribute 'data'
unit-postgresql-k8s-1: 01:43:15 ERROR juju.worker.uniter.operation hook "postgresql-pebble-ready" (via hook dispatching script: dispatch) failed: exit status 1
unit-postgresql-k8s-1: 01:43:15 ERROR juju.worker.uniter pebble poll failed for container "postgresql": failed to send pebble-ready event: hook failed
unit-postgresql-k8s-2: 01:43:28 ERROR unit.postgresql-k8s/2.juju-log Failed to list PostgreSQL database users: connection to server at "postgresql-k8s-primary.test.svc.cluster.local" (10.152.183.51), port 5432 failed: FATAL:  password authentication failed for user "operator"

unit-postgresql-k8s-2: 01:43:28 ERROR unit.postgresql-k8s/2.juju-log Uncaught exception while in charm code:
Traceback (most recent call last):
  File "/var/lib/juju/agents/unit-postgresql-k8s-2/charm/lib/charms/postgresql_k8s/v0/postgresql.py", line 496, in list_users
    with self._connect_to_database() as connection, connection.cursor() as cursor:
  File "/var/lib/juju/agents/unit-postgresql-k8s-2/charm/lib/charms/tempo_coordinator_k8s/v0/charm_tracing.py", line 734, in wrapped_function
    return callable(*args, **kwargs)  # type: ignore
  File "/var/lib/juju/agents/unit-postgresql-k8s-2/charm/lib/charms/postgresql_k8s/v0/postgresql.py", line 150, in _connect_to_database
    connection = psycopg2.connect(
  File "/var/lib/juju/agents/unit-postgresql-k8s-2/charm/venv/psycopg2/__init__.py", line 122, in connect
    conn = _connect(dsn, connection_factory=connection_factory, **kwasync)
psycopg2.OperationalError: connection to server at "postgresql-k8s-primary.test.svc.cluster.local" (10.152.183.51), port 5432 failed: FATAL:  password authentication failed for user "operator"


During handling of the above exception, another exception occurred:

Traceback (most recent call last):
  File "/var/lib/juju/agents/unit-postgresql-k8s-2/charm/./src/charm.py", line 2202, in <module>
    main(PostgresqlOperatorCharm, use_juju_for_storage=True)
  File "/var/lib/juju/agents/unit-postgresql-k8s-2/charm/venv/ops/__init__.py", line 343, in __call__
    return _main.main(charm_class=charm_class, use_juju_for_storage=use_juju_for_storage)
  File "/var/lib/juju/agents/unit-postgresql-k8s-2/charm/venv/ops/_main.py", line 543, in main
    manager.run()
  File "/var/lib/juju/agents/unit-postgresql-k8s-2/charm/venv/ops/_main.py", line 529, in run
    self._emit()
  File "/var/lib/juju/agents/unit-postgresql-k8s-2/charm/venv/ops/_main.py", line 518, in _emit
    _emit_charm_event(self.charm, self.dispatcher.event_name, self._juju_context)
  File "/var/lib/juju/agents/unit-postgresql-k8s-2/charm/venv/ops/_main.py", line 134, in _emit_charm_event
    event_to_emit.emit(*args, **kwargs)
  File "/var/lib/juju/agents/unit-postgresql-k8s-2/charm/venv/ops/framework.py", line 347, in emit
    framework._emit(event)
  File "/var/lib/juju/agents/unit-postgresql-k8s-2/charm/venv/ops/framework.py", line 857, in _emit
    self._reemit(event_path)
  File "/var/lib/juju/agents/unit-postgresql-k8s-2/charm/venv/ops/framework.py", line 947, in _reemit
    custom_handler(event)
  File "/var/lib/juju/agents/unit-postgresql-k8s-2/charm/lib/charms/tempo_coordinator_k8s/v0/charm_tracing.py", line 734, in wrapped_function
    return callable(*args, **kwargs)  # type: ignore
  File "/var/lib/juju/agents/unit-postgresql-k8s-2/charm/./src/charm.py", line 949, in _on_postgresql_pebble_ready
    if self.unit.is_leader() and not self._initialize_cluster(event):
  File "/var/lib/juju/agents/unit-postgresql-k8s-2/charm/lib/charms/tempo_coordinator_k8s/v0/charm_tracing.py", line 734, in wrapped_function
    return callable(*args, **kwargs)  # type: ignore
  File "/var/lib/juju/agents/unit-postgresql-k8s-2/charm/./src/charm.py", line 1025, in _initialize_cluster
    pg_users = self.postgresql.list_users()
  File "/var/lib/juju/agents/unit-postgresql-k8s-2/charm/lib/charms/tempo_coordinator_k8s/v0/charm_tracing.py", line 734, in wrapped_function
    return callable(*args, **kwargs)  # type: ignore
  File "/var/lib/juju/agents/unit-postgresql-k8s-2/charm/lib/charms/postgresql_k8s/v0/postgresql.py", line 502, in list_users
    raise PostgreSQLListUsersError()
charms.postgresql_k8s.v0.postgresql.PostgreSQLListUsersError
unit-postgresql-k8s-2: 01:43:28 ERROR juju.worker.uniter.operation hook "postgresql-pebble-ready" (via hook dispatching script: dispatch) failed: exit status 1
unit-postgresql-k8s-2: 01:43:28 ERROR juju.worker.dependency "uniter" manifold worker returned unexpected error: relation scope id "f0479be4-e6cf-4eef-8fae-1eb28740cb32:r#3#postgresql-k8s": settings f0479be4-e6cf-4eef-8fae-1eb28740cb32:r#3#postgresql-k8s not found (not found)

[32mINFO    [0m pytest_operator.plugin:plugin.py:991 Forgetting model main...