[32mINFO    [0m pytest_operator.plugin:plugin.py:834 Model status:

Model  Controller          Cloud/Region        Version  SLA          Timestamp
test   microk8s-localhost  microk8s/localhost  3.1.8    unsupported  01:36:51Z

App                       Version  Status       Scale  Charm                     Channel        Rev  Address         Exposed  Message
data-integrator                    active           1  data-integrator           latest/edge     27  10.152.183.144  no       
pgbouncer-k8s             1.21.0   active           1  pgbouncer-k8s                              0  10.152.183.240  no       
postgresql-k8s            14.11    maintenance      3  postgresql-k8s            14/edge        239  10.152.183.246  no       Beginning rolling restart
postgresql-test-app                active           1  postgresql-test-app       edge           115  10.152.183.67   no       received database credentials of the first database
self-signed-certificates           active           1  self-signed-certificates  latest/stable   72  10.152.183.115  no       

Unit                         Workload  Agent  Address       Ports  Message
data-integrator/0*           active    idle   10.1.132.201         
pgbouncer-k8s/0*             active    idle   10.1.132.200         
postgresql-k8s/0             waiting   idle   10.1.132.206         awaiting for member to start
postgresql-k8s/1             active    idle   10.1.132.207         
postgresql-k8s/2*            waiting   idle   10.1.132.208         Awaiting restart operation
postgresql-test-app/0*       active    idle   10.1.132.202         received database credentials of the first database
self-signed-certificates/0*  active    idle   10.1.132.209         

[32mINFO    [0m pytest_operator.plugin:plugin.py:840 Juju error logs:

unit-postgresql-k8s-2: 01:36:50 ERROR unit.postgresql-k8s/2.juju-log Uncaught exception while in charm code:
Traceback (most recent call last):
  File "/var/lib/juju/agents/unit-postgresql-k8s-2/charm/venv/urllib3/connectionpool.py", line 467, in _make_request
    self._validate_conn(conn)
  File "/var/lib/juju/agents/unit-postgresql-k8s-2/charm/venv/urllib3/connectionpool.py", line 1099, in _validate_conn
    conn.connect()
  File "/var/lib/juju/agents/unit-postgresql-k8s-2/charm/venv/urllib3/connection.py", line 653, in connect
    sock_and_verified = _ssl_wrap_socket_and_match_hostname(
  File "/var/lib/juju/agents/unit-postgresql-k8s-2/charm/venv/urllib3/connection.py", line 806, in _ssl_wrap_socket_and_match_hostname
    ssl_sock = ssl_wrap_socket(
  File "/var/lib/juju/agents/unit-postgresql-k8s-2/charm/venv/urllib3/util/ssl_.py", line 465, in ssl_wrap_socket
    ssl_sock = _ssl_wrap_socket_impl(sock, context, tls_in_tls, server_hostname)
  File "/var/lib/juju/agents/unit-postgresql-k8s-2/charm/venv/urllib3/util/ssl_.py", line 509, in _ssl_wrap_socket_impl
    return ssl_context.wrap_socket(sock, server_hostname=server_hostname)
  File "/usr/lib/python3.10/ssl.py", line 513, in wrap_socket
    return self.sslsocket_class._create(
  File "/usr/lib/python3.10/ssl.py", line 1100, in _create
    self.do_handshake()
  File "/usr/lib/python3.10/ssl.py", line 1371, in do_handshake
    self._sslobj.do_handshake()
ssl.SSLError: [SSL: WRONG_VERSION_NUMBER] wrong version number (_ssl.c:1007)

During handling of the above exception, another exception occurred:

Traceback (most recent call last):
  File "/var/lib/juju/agents/unit-postgresql-k8s-2/charm/venv/urllib3/connectionpool.py", line 793, in urlopen
    response = self._make_request(
  File "/var/lib/juju/agents/unit-postgresql-k8s-2/charm/venv/urllib3/connectionpool.py", line 491, in _make_request
    raise new_e
urllib3.exceptions.SSLError: [SSL: WRONG_VERSION_NUMBER] wrong version number (_ssl.c:1007)

The above exception was the direct cause of the following exception:

Traceback (most recent call last):
  File "/var/lib/juju/agents/unit-postgresql-k8s-2/charm/venv/requests/adapters.py", line 486, in send
    resp = conn.urlopen(
  File "/var/lib/juju/agents/unit-postgresql-k8s-2/charm/venv/urllib3/connectionpool.py", line 847, in urlopen
    retries = retries.increment(
  File "/var/lib/juju/agents/unit-postgresql-k8s-2/charm/venv/urllib3/util/retry.py", line 515, in increment
    raise MaxRetryError(_pool, url, reason) from reason  # type: ignore[arg-type]
urllib3.exceptions.MaxRetryError: HTTPSConnectionPool(host='postgresql-k8s-2.postgresql-k8s-endpoints', port=8008): Max retries exceeded with url: /cluster (Caused by SSLError(SSLError(1, '[SSL: WRONG_VERSION_NUMBER] wrong version number (_ssl.c:1007)')))

During handling of the above exception, another exception occurred:

Traceback (most recent call last):
  File "/var/lib/juju/agents/unit-postgresql-k8s-2/charm/venv/tenacity/__init__.py", line 382, in __call__
    result = fn(*args, **kwargs)
  File "/var/lib/juju/agents/unit-postgresql-k8s-2/charm/src/patroni.py", line 148, in cluster_members
    r = requests.get(f"{self._patroni_url}/cluster", verify=self._verify)
  File "/var/lib/juju/agents/unit-postgresql-k8s-2/charm/venv/requests/api.py", line 73, in get
    return request("get", url, params=params, **kwargs)
  File "/var/lib/juju/agents/unit-postgresql-k8s-2/charm/venv/requests/api.py", line 59, in request
    return session.request(method=method, url=url, **kwargs)
  File "/var/lib/juju/agents/unit-postgresql-k8s-2/charm/venv/requests/sessions.py", line 589, in request
    resp = self.send(prep, **send_kwargs)
  File "/var/lib/juju/agents/unit-postgresql-k8s-2/charm/venv/requests/sessions.py", line 703, in send
    r = adapter.send(request, **kwargs)
  File "/var/lib/juju/agents/unit-postgresql-k8s-2/charm/venv/requests/adapters.py", line 517, in send
    raise SSLError(e, request=request)
requests.exceptions.SSLError: HTTPSConnectionPool(host='postgresql-k8s-2.postgresql-k8s-endpoints', port=8008): Max retries exceeded with url: /cluster (Caused by SSLError(SSLError(1, '[SSL: WRONG_VERSION_NUMBER] wrong version number (_ssl.c:1007)')))

The above exception was the direct cause of the following exception:

Traceback (most recent call last):
  File "/var/lib/juju/agents/unit-postgresql-k8s-2/charm/./src/charm.py", line 1630, in <module>
    main(PostgresqlOperatorCharm, use_juju_for_storage=True)
  File "/var/lib/juju/agents/unit-postgresql-k8s-2/charm/venv/ops/main.py", line 544, in main
    manager.run()
  File "/var/lib/juju/agents/unit-postgresql-k8s-2/charm/venv/ops/main.py", line 520, in run
    self._emit()
  File "/var/lib/juju/agents/unit-postgresql-k8s-2/charm/venv/ops/main.py", line 509, in _emit
    _emit_charm_event(self.charm, self.dispatcher.event_name)
  File "/var/lib/juju/agents/unit-postgresql-k8s-2/charm/venv/ops/main.py", line 143, in _emit_charm_event
    event_to_emit.emit(*args, **kwargs)
  File "/var/lib/juju/agents/unit-postgresql-k8s-2/charm/venv/ops/framework.py", line 352, in emit
    framework._emit(event)
  File "/var/lib/juju/agents/unit-postgresql-k8s-2/charm/venv/ops/framework.py", line 851, in _emit
    self._reemit(event_path)
  File "/var/lib/juju/agents/unit-postgresql-k8s-2/charm/venv/ops/framework.py", line 941, in _reemit
    custom_handler(event)
  File "/var/lib/juju/agents/unit-postgresql-k8s-2/charm/./src/charm.py", line 384, in _on_peer_relation_changed
    self._add_members(event)
  File "/var/lib/juju/agents/unit-postgresql-k8s-2/charm/./src/charm.py", line 564, in _add_members
    if self._patroni.cluster_members == self._hosts:
  File "/var/lib/juju/agents/unit-postgresql-k8s-2/charm/venv/tenacity/__init__.py", line 289, in wrapped_f
    return self(f, *args, **kw)
  File "/var/lib/juju/agents/unit-postgresql-k8s-2/charm/venv/tenacity/__init__.py", line 379, in __call__
    do = self.iter(retry_state=retry_state)
  File "/var/lib/juju/agents/unit-postgresql-k8s-2/charm/venv/tenacity/__init__.py", line 326, in iter
    raise retry_exc from fut.exception()
tenacity.RetryError: RetryError[<Future at 0x7fe747d47d90 state=finished raised SSLError>]
unit-postgresql-k8s-2: 01:36:50 ERROR juju.worker.uniter.operation hook "secret-changed" (via hook dispatching script: dispatch) failed: exit status 1

[32mINFO    [0m pytest_operator.plugin:plugin.py:904 Forgetting main...